[2025-10-07T08:00:03.971+0000] {local_task_job_runner.py:120} INFO - ::group::Pre task execution logs
[2025-10-07T08:00:04.016+0000] {taskinstance.py:2076} INFO - Dependencies all met for dep_context=non-requeueable deps ti=<TaskInstance: restaurant_analytics.run_spark_stream scheduled__2025-10-07T07:00:00+00:00 [queued]>
[2025-10-07T08:00:04.033+0000] {taskinstance.py:2076} INFO - Dependencies all met for dep_context=requeueable deps ti=<TaskInstance: restaurant_analytics.run_spark_stream scheduled__2025-10-07T07:00:00+00:00 [queued]>
[2025-10-07T08:00:04.043+0000] {taskinstance.py:2306} INFO - Starting attempt 1 of 2
[2025-10-07T08:00:04.065+0000] {taskinstance.py:2330} INFO - Executing <Task(BashOperator): run_spark_stream> on 2025-10-07 07:00:00+00:00
[2025-10-07T08:00:04.076+0000] {standard_task_runner.py:64} INFO - Started process 3386 to run task
[2025-10-07T08:00:04.082+0000] {standard_task_runner.py:90} INFO - Running: ['***', 'tasks', 'run', 'restaurant_analytics', 'run_spark_stream', 'scheduled__2025-10-07T07:00:00+00:00', '--job-id', '26', '--raw', '--subdir', 'DAGS_FOLDER/restaurant_dag.py', '--cfg-path', '/tmp/tmp0z4tr_yb']
[2025-10-07T08:00:04.087+0000] {standard_task_runner.py:91} INFO - Job 26: Subtask run_spark_stream
[2025-10-07T08:00:04.218+0000] {task_command.py:426} INFO - Running <TaskInstance: restaurant_analytics.run_spark_stream scheduled__2025-10-07T07:00:00+00:00 [running]> on host 50743b1a3092
[2025-10-07T08:00:04.415+0000] {taskinstance.py:2648} INFO - Exporting env vars: AIRFLOW_CTX_DAG_EMAIL='quantruong1918@gmail.com' AIRFLOW_CTX_DAG_OWNER='***' AIRFLOW_CTX_DAG_ID='restaurant_analytics' AIRFLOW_CTX_TASK_ID='run_spark_stream' AIRFLOW_CTX_EXECUTION_DATE='2025-10-07T07:00:00+00:00' AIRFLOW_CTX_TRY_NUMBER='1' AIRFLOW_CTX_DAG_RUN_ID='scheduled__2025-10-07T07:00:00+00:00'
[2025-10-07T08:00:04.422+0000] {taskinstance.py:430} INFO - ::endgroup::
[2025-10-07T08:00:04.426+0000] {subprocess.py:63} INFO - Tmp dir root location: /tmp
[2025-10-07T08:00:04.429+0000] {subprocess.py:75} INFO - Running command: ['/usr/bin/bash', '-c', 'spark-submit --master local[*] /opt/***/dags/spark_streaming.py']
[2025-10-07T08:00:04.461+0000] {subprocess.py:86} INFO - Output:
[2025-10-07T08:00:04.463+0000] {subprocess.py:93} INFO - /usr/bin/bash: line 1: spark-submit: command not found
[2025-10-07T08:00:04.464+0000] {subprocess.py:97} INFO - Command exited with return code 127
[2025-10-07T08:00:04.466+0000] {taskinstance.py:441} INFO - ::group::Post task execution logs
[2025-10-07T08:00:04.483+0000] {taskinstance.py:2905} ERROR - Task failed with exception
Traceback (most recent call last):
  File "/home/airflow/.local/lib/python3.9/site-packages/airflow/models/taskinstance.py", line 465, in _execute_task
    result = _execute_callable(context=context, **execute_callable_kwargs)
  File "/home/airflow/.local/lib/python3.9/site-packages/airflow/models/taskinstance.py", line 432, in _execute_callable
    return execute_callable(context=context, **execute_callable_kwargs)
  File "/home/airflow/.local/lib/python3.9/site-packages/airflow/models/baseoperator.py", line 401, in wrapper
    return func(self, *args, **kwargs)
  File "/home/airflow/.local/lib/python3.9/site-packages/airflow/operators/bash.py", line 243, in execute
    raise AirflowException(
airflow.exceptions.AirflowException: Bash command failed. The command returned a non-zero exit code 127.
[2025-10-07T08:00:04.494+0000] {taskinstance.py:1206} INFO - Marking task as UP_FOR_RETRY. dag_id=restaurant_analytics, task_id=run_spark_stream, run_id=scheduled__2025-10-07T07:00:00+00:00, execution_date=20251007T070000, start_date=20251007T080004, end_date=20251007T080004
[2025-10-07T08:00:04.527+0000] {warnings.py:109} WARNING - /home/***/.local/lib/python3.9/site-packages/***/utils/email.py:154: RemovedInAirflow3Warning: Fetching SMTP credentials from configuration variables will be deprecated in a future release. Please set credentials using a connection instead.
  send_mime_email(e_from=mail_from, e_to=recipients, mime_msg=msg, conn_id=conn_id, dryrun=dryrun)

[2025-10-07T08:00:04.529+0000] {configuration.py:1053} WARNING - section/key [smtp/smtp_user] not found in config
[2025-10-07T08:00:04.530+0000] {email.py:271} INFO - Email alerting: attempt 1
[2025-10-07T08:00:04.544+0000] {configuration.py:1053} WARNING - section/key [smtp/smtp_user] not found in config
[2025-10-07T08:00:04.545+0000] {email.py:271} INFO - Email alerting: attempt 1
[2025-10-07T08:00:04.547+0000] {taskinstance.py:879} ERROR - Failed to send email to: ['quantruong1918@gmail.com']
Traceback (most recent call last):
  File "/home/airflow/.local/lib/python3.9/site-packages/airflow/models/taskinstance.py", line 2479, in _run_raw_task
    self._execute_task_with_callbacks(context, test_mode, session=session)
  File "/home/airflow/.local/lib/python3.9/site-packages/airflow/models/taskinstance.py", line 2676, in _execute_task_with_callbacks
    result = self._execute_task(context, task_orig)
  File "/home/airflow/.local/lib/python3.9/site-packages/airflow/models/taskinstance.py", line 2701, in _execute_task
    return _execute_task(self, context, task_orig)
  File "/home/airflow/.local/lib/python3.9/site-packages/airflow/models/taskinstance.py", line 465, in _execute_task
    result = _execute_callable(context=context, **execute_callable_kwargs)
  File "/home/airflow/.local/lib/python3.9/site-packages/airflow/models/taskinstance.py", line 432, in _execute_callable
    return execute_callable(context=context, **execute_callable_kwargs)
  File "/home/airflow/.local/lib/python3.9/site-packages/airflow/models/baseoperator.py", line 401, in wrapper
    return func(self, *args, **kwargs)
  File "/home/airflow/.local/lib/python3.9/site-packages/airflow/operators/bash.py", line 243, in execute
    raise AirflowException(
airflow.exceptions.AirflowException: Bash command failed. The command returned a non-zero exit code 127.

During handling of the above exception, another exception occurred:

Traceback (most recent call last):
  File "/home/airflow/.local/lib/python3.9/site-packages/airflow/models/taskinstance.py", line 1063, in _email_alert
    send_email(task.email, subject, html_content)
  File "/home/airflow/.local/lib/python3.9/site-packages/airflow/utils/email.py", line 80, in send_email
    return backend(
  File "/home/airflow/.local/lib/python3.9/site-packages/airflow/utils/email.py", line 154, in send_email_smtp
    send_mime_email(e_from=mail_from, e_to=recipients, mime_msg=msg, conn_id=conn_id, dryrun=dryrun)
  File "/home/airflow/.local/lib/python3.9/site-packages/airflow/utils/email.py", line 273, in send_mime_email
    smtp_conn = _get_smtp_connection(smtp_host, smtp_port, smtp_timeout, smtp_ssl)
  File "/home/airflow/.local/lib/python3.9/site-packages/airflow/utils/email.py", line 317, in _get_smtp_connection
    return smtplib.SMTP(host=host, port=port, timeout=timeout)
  File "/usr/local/lib/python3.9/smtplib.py", line 255, in __init__
    (code, msg) = self.connect(host, port)
  File "/usr/local/lib/python3.9/smtplib.py", line 341, in connect
    self.sock = self._get_socket(host, port, self.timeout)
  File "/usr/local/lib/python3.9/smtplib.py", line 312, in _get_socket
    return socket.create_connection((host, port), timeout,
  File "/usr/local/lib/python3.9/socket.py", line 844, in create_connection
    raise err
  File "/usr/local/lib/python3.9/socket.py", line 832, in create_connection
    sock.connect(sa)
ConnectionRefusedError: [Errno 111] Connection refused

During handling of the above exception, another exception occurred:

Traceback (most recent call last):
  File "/home/airflow/.local/lib/python3.9/site-packages/airflow/models/taskinstance.py", line 877, in _handle_failure
    task_instance.email_alert(error, failure_context["task"])
  File "/home/airflow/.local/lib/python3.9/site-packages/airflow/models/taskinstance.py", line 3163, in email_alert
    _email_alert(task_instance=self, exception=exception, task=task)
  File "/home/airflow/.local/lib/python3.9/site-packages/airflow/models/taskinstance.py", line 1065, in _email_alert
    send_email(task.email, subject, html_content_err)
  File "/home/airflow/.local/lib/python3.9/site-packages/airflow/utils/email.py", line 80, in send_email
    return backend(
  File "/home/airflow/.local/lib/python3.9/site-packages/airflow/utils/email.py", line 154, in send_email_smtp
    send_mime_email(e_from=mail_from, e_to=recipients, mime_msg=msg, conn_id=conn_id, dryrun=dryrun)
  File "/home/airflow/.local/lib/python3.9/site-packages/airflow/utils/email.py", line 273, in send_mime_email
    smtp_conn = _get_smtp_connection(smtp_host, smtp_port, smtp_timeout, smtp_ssl)
  File "/home/airflow/.local/lib/python3.9/site-packages/airflow/utils/email.py", line 317, in _get_smtp_connection
    return smtplib.SMTP(host=host, port=port, timeout=timeout)
  File "/usr/local/lib/python3.9/smtplib.py", line 255, in __init__
    (code, msg) = self.connect(host, port)
  File "/usr/local/lib/python3.9/smtplib.py", line 341, in connect
    self.sock = self._get_socket(host, port, self.timeout)
  File "/usr/local/lib/python3.9/smtplib.py", line 312, in _get_socket
    return socket.create_connection((host, port), timeout,
  File "/usr/local/lib/python3.9/socket.py", line 844, in create_connection
    raise err
  File "/usr/local/lib/python3.9/socket.py", line 832, in create_connection
    sock.connect(sa)
ConnectionRefusedError: [Errno 111] Connection refused
[2025-10-07T08:00:04.578+0000] {standard_task_runner.py:110} ERROR - Failed to execute job 26 for task run_spark_stream (Bash command failed. The command returned a non-zero exit code 127.; 3386)
[2025-10-07T08:00:04.617+0000] {local_task_job_runner.py:243} INFO - Task exited with return code 1
[2025-10-07T08:00:04.647+0000] {taskinstance.py:3503} INFO - 0 downstream tasks scheduled from follow-on schedule check
[2025-10-07T08:00:04.652+0000] {local_task_job_runner.py:222} INFO - ::endgroup::
