[2025-10-09T15:43:52.632+0000] {local_task_job_runner.py:120} INFO - ::group::Pre task execution logs
[2025-10-09T15:43:52.729+0000] {taskinstance.py:2076} INFO - Dependencies all met for dep_context=non-requeueable deps ti=<TaskInstance: restaurant_analytics.retrain_model manual__2025-10-09T15:43:30.208014+00:00 [queued]>
[2025-10-09T15:43:52.755+0000] {taskinstance.py:2076} INFO - Dependencies all met for dep_context=requeueable deps ti=<TaskInstance: restaurant_analytics.retrain_model manual__2025-10-09T15:43:30.208014+00:00 [queued]>
[2025-10-09T15:43:52.767+0000] {taskinstance.py:2306} INFO - Starting attempt 1 of 2
[2025-10-09T15:43:52.808+0000] {taskinstance.py:2330} INFO - Executing <Task(BashOperator): retrain_model> on 2025-10-09 15:43:30.208014+00:00
[2025-10-09T15:43:52.840+0000] {warnings.py:112} WARNING - /home/***/.local/lib/python3.12/site-packages/***/task/task_runner/standard_task_runner.py:62: DeprecationWarning: This process (pid=3517) is multi-threaded, use of fork() may lead to deadlocks in the child.
  pid = os.fork()

[2025-10-09T15:43:52.846+0000] {standard_task_runner.py:64} INFO - Started process 3526 to run task
[2025-10-09T15:43:52.847+0000] {standard_task_runner.py:90} INFO - Running: ['***', 'tasks', 'run', 'restaurant_analytics', 'retrain_model', 'manual__2025-10-09T15:43:30.208014+00:00', '--job-id', '271', '--raw', '--subdir', 'DAGS_FOLDER/restaurant_dag.py', '--cfg-path', '/tmp/tmp4zvg372i']
[2025-10-09T15:43:52.853+0000] {standard_task_runner.py:91} INFO - Job 271: Subtask retrain_model
[2025-10-09T15:43:53.049+0000] {task_command.py:426} INFO - Running <TaskInstance: restaurant_analytics.retrain_model manual__2025-10-09T15:43:30.208014+00:00 [running]> on host dd5baa7fba45
[2025-10-09T15:43:53.494+0000] {taskinstance.py:2648} INFO - Exporting env vars: AIRFLOW_CTX_DAG_EMAIL='quantruong1918@gmail.com' AIRFLOW_CTX_DAG_OWNER='***' AIRFLOW_CTX_DAG_ID='restaurant_analytics' AIRFLOW_CTX_TASK_ID='retrain_model' AIRFLOW_CTX_EXECUTION_DATE='2025-10-09T15:43:30.208014+00:00' AIRFLOW_CTX_TRY_NUMBER='1' AIRFLOW_CTX_DAG_RUN_ID='manual__2025-10-09T15:43:30.208014+00:00'
[2025-10-09T15:43:53.513+0000] {taskinstance.py:430} INFO - ::endgroup::
[2025-10-09T15:43:53.525+0000] {subprocess.py:63} INFO - Tmp dir root location: /tmp
[2025-10-09T15:43:53.536+0000] {subprocess.py:75} INFO - Running command: ['/usr/bin/bash', '-c', 'export PYSPARK_PYTHON=/usr/local/bin/python && export PYSPARK_DRIVER_PYTHON=/usr/local/bin/python && /opt/spark/bin/spark-submit --master local[*] /opt/***/dags/train_lr.py']
[2025-10-09T15:43:53.642+0000] {subprocess.py:86} INFO - Output:
[2025-10-09T15:44:16.392+0000] {subprocess.py:93} INFO - 25/10/09 15:44:16 INFO SparkContext: Running Spark version 3.5.1
[2025-10-09T15:44:16.402+0000] {subprocess.py:93} INFO - 25/10/09 15:44:16 INFO SparkContext: OS info Linux, 6.6.87.1-microsoft-standard-WSL2, amd64
[2025-10-09T15:44:16.405+0000] {subprocess.py:93} INFO - 25/10/09 15:44:16 INFO SparkContext: Java version 17.0.16
[2025-10-09T15:44:16.673+0000] {subprocess.py:93} INFO - 25/10/09 15:44:16 WARN NativeCodeLoader: Unable to load native-hadoop library for your platform... using builtin-java classes where applicable
[2025-10-09T15:44:16.983+0000] {subprocess.py:93} INFO - 25/10/09 15:44:16 INFO ResourceUtils: ==============================================================
[2025-10-09T15:44:16.987+0000] {subprocess.py:93} INFO - 25/10/09 15:44:16 INFO ResourceUtils: No custom resources configured for spark.driver.
[2025-10-09T15:44:16.989+0000] {subprocess.py:93} INFO - 25/10/09 15:44:16 INFO ResourceUtils: ==============================================================
[2025-10-09T15:44:16.990+0000] {subprocess.py:93} INFO - 25/10/09 15:44:16 INFO SparkContext: Submitted application: TrainLR
[2025-10-09T15:44:17.059+0000] {subprocess.py:93} INFO - 25/10/09 15:44:17 INFO ResourceProfile: Default ResourceProfile created, executor resources: Map(cores -> name: cores, amount: 1, script: , vendor: , memory -> name: memory, amount: 1024, script: , vendor: , offHeap -> name: offHeap, amount: 0, script: , vendor: ), task resources: Map(cpus -> name: cpus, amount: 1.0)
[2025-10-09T15:44:17.084+0000] {subprocess.py:93} INFO - 25/10/09 15:44:17 INFO ResourceProfile: Limiting resource is cpu
[2025-10-09T15:44:17.086+0000] {subprocess.py:93} INFO - 25/10/09 15:44:17 INFO ResourceProfileManager: Added ResourceProfile id: 0
[2025-10-09T15:44:17.245+0000] {subprocess.py:93} INFO - 25/10/09 15:44:17 INFO SecurityManager: Changing view acls to: ***
[2025-10-09T15:44:17.247+0000] {subprocess.py:93} INFO - 25/10/09 15:44:17 INFO SecurityManager: Changing modify acls to: ***
[2025-10-09T15:44:17.250+0000] {subprocess.py:93} INFO - 25/10/09 15:44:17 INFO SecurityManager: Changing view acls groups to:
[2025-10-09T15:44:17.253+0000] {subprocess.py:93} INFO - 25/10/09 15:44:17 INFO SecurityManager: Changing modify acls groups to:
[2025-10-09T15:44:17.258+0000] {subprocess.py:93} INFO - 25/10/09 15:44:17 INFO SecurityManager: SecurityManager: authentication disabled; ui acls disabled; users with view permissions: ***; groups with view permissions: EMPTY; users with modify permissions: ***; groups with modify permissions: EMPTY
[2025-10-09T15:44:18.327+0000] {subprocess.py:93} INFO - 25/10/09 15:44:18 INFO Utils: Successfully started service 'sparkDriver' on port 44753.
[2025-10-09T15:44:18.738+0000] {subprocess.py:93} INFO - 25/10/09 15:44:18 INFO SparkEnv: Registering MapOutputTracker
[2025-10-09T15:44:19.131+0000] {subprocess.py:93} INFO - 25/10/09 15:44:19 INFO SparkEnv: Registering BlockManagerMaster
[2025-10-09T15:44:19.239+0000] {subprocess.py:93} INFO - 25/10/09 15:44:19 INFO BlockManagerMasterEndpoint: Using org.apache.spark.storage.DefaultTopologyMapper for getting topology information
[2025-10-09T15:44:19.242+0000] {subprocess.py:93} INFO - 25/10/09 15:44:19 INFO BlockManagerMasterEndpoint: BlockManagerMasterEndpoint up
[2025-10-09T15:44:19.289+0000] {subprocess.py:93} INFO - 25/10/09 15:44:19 INFO SparkEnv: Registering BlockManagerMasterHeartbeat
[2025-10-09T15:44:19.579+0000] {subprocess.py:93} INFO - 25/10/09 15:44:19 INFO DiskBlockManager: Created local directory at /tmp/blockmgr-3b0c3518-a72d-4ef2-8ecf-6912bda5abed
[2025-10-09T15:44:19.702+0000] {subprocess.py:93} INFO - 25/10/09 15:44:19 INFO MemoryStore: MemoryStore started with capacity 434.4 MiB
[2025-10-09T15:44:19.842+0000] {subprocess.py:93} INFO - 25/10/09 15:44:19 INFO SparkEnv: Registering OutputCommitCoordinator
[2025-10-09T15:44:21.457+0000] {subprocess.py:93} INFO - 25/10/09 15:44:21 INFO JettyUtils: Start Jetty 0.0.0.0:4040 for SparkUI
[2025-10-09T15:44:22.162+0000] {subprocess.py:93} INFO - 25/10/09 15:44:22 INFO Utils: Successfully started service 'SparkUI' on port 4040.
[2025-10-09T15:44:23.199+0000] {subprocess.py:93} INFO - 25/10/09 15:44:23 INFO Executor: Starting executor ID driver on host dd5baa7fba45
[2025-10-09T15:44:23.204+0000] {subprocess.py:93} INFO - 25/10/09 15:44:23 INFO Executor: OS info Linux, 6.6.87.1-microsoft-standard-WSL2, amd64
[2025-10-09T15:44:23.208+0000] {subprocess.py:93} INFO - 25/10/09 15:44:23 INFO Executor: Java version 17.0.16
[2025-10-09T15:44:23.279+0000] {subprocess.py:93} INFO - 25/10/09 15:44:23 INFO Executor: Starting executor with user classpath (userClassPathFirst = false): ''
[2025-10-09T15:44:23.287+0000] {subprocess.py:93} INFO - 25/10/09 15:44:23 INFO Executor: Created or updated repl class loader org.apache.spark.util.MutableURLClassLoader@282a31fd for default.
[2025-10-09T15:44:23.421+0000] {subprocess.py:93} INFO - 25/10/09 15:44:23 INFO Utils: Successfully started service 'org.apache.spark.network.netty.NettyBlockTransferService' on port 45957.
[2025-10-09T15:44:23.427+0000] {subprocess.py:93} INFO - 25/10/09 15:44:23 INFO NettyBlockTransferService: Server created on dd5baa7fba45:45957
[2025-10-09T15:44:23.445+0000] {subprocess.py:93} INFO - 25/10/09 15:44:23 INFO BlockManager: Using org.apache.spark.storage.RandomBlockReplicationPolicy for block replication policy
[2025-10-09T15:44:23.505+0000] {subprocess.py:93} INFO - 25/10/09 15:44:23 INFO BlockManagerMaster: Registering BlockManager BlockManagerId(driver, dd5baa7fba45, 45957, None)
[2025-10-09T15:44:23.537+0000] {subprocess.py:93} INFO - 25/10/09 15:44:23 INFO BlockManagerMasterEndpoint: Registering block manager dd5baa7fba45:45957 with 434.4 MiB RAM, BlockManagerId(driver, dd5baa7fba45, 45957, None)
[2025-10-09T15:44:23.550+0000] {subprocess.py:93} INFO - 25/10/09 15:44:23 INFO BlockManagerMaster: Registered BlockManager BlockManagerId(driver, dd5baa7fba45, 45957, None)
[2025-10-09T15:44:23.561+0000] {subprocess.py:93} INFO - 25/10/09 15:44:23 INFO BlockManager: Initialized BlockManager: BlockManagerId(driver, dd5baa7fba45, 45957, None)
[2025-10-09T15:44:25.883+0000] {subprocess.py:93} INFO - 25/10/09 15:44:25 INFO SharedState: Setting hive.metastore.warehouse.dir ('null') to the value of spark.sql.warehouse.dir.
[2025-10-09T15:44:25.929+0000] {subprocess.py:93} INFO - 25/10/09 15:44:25 INFO SharedState: Warehouse path is 'file:/tmp/***tmpgzammqtb/spark-warehouse'.
[2025-10-09T15:44:30.818+0000] {subprocess.py:93} INFO - Traceback (most recent call last):
[2025-10-09T15:44:30.819+0000] {subprocess.py:93} INFO -   File "/opt/***/dags/train_lr.py", line 7, in <module>
[2025-10-09T15:44:30.826+0000] {subprocess.py:93} INFO -     df = spark.read.csv('historical_orders.csv', header=True, inferSchema=True)
[2025-10-09T15:44:30.829+0000] {subprocess.py:93} INFO -          ^^^^^^^^^^^^^^^^^^^^^^^^^^^^^^^^^^^^^^^^^^^^^^^^^^^^^^^^^^^^^^^^^^^^^^
[2025-10-09T15:44:30.832+0000] {subprocess.py:93} INFO -   File "/opt/spark/python/lib/pyspark.zip/pyspark/sql/readwriter.py", line 740, in csv
[2025-10-09T15:44:30.833+0000] {subprocess.py:93} INFO -   File "/opt/spark/python/lib/py4j-0.10.9.7-src.zip/py4j/java_gateway.py", line 1322, in __call__
[2025-10-09T15:44:30.835+0000] {subprocess.py:93} INFO -   File "/opt/spark/python/lib/pyspark.zip/pyspark/errors/exceptions/captured.py", line 185, in deco
[2025-10-09T15:44:30.860+0000] {subprocess.py:93} INFO - pyspark.errors.exceptions.captured.AnalysisException: [PATH_NOT_FOUND] Path does not exist: file:/tmp/***tmpgzammqtb/historical_orders.csv.
[2025-10-09T15:44:31.106+0000] {subprocess.py:93} INFO - 25/10/09 15:44:31 INFO SparkContext: Invoking stop() from shutdown hook
[2025-10-09T15:44:31.107+0000] {subprocess.py:93} INFO - 25/10/09 15:44:31 INFO SparkContext: SparkContext is stopping with exitCode 0.
[2025-10-09T15:44:31.134+0000] {subprocess.py:93} INFO - 25/10/09 15:44:31 INFO SparkUI: Stopped Spark web UI at http://dd5baa7fba45:4040
[2025-10-09T15:44:31.159+0000] {subprocess.py:93} INFO - 25/10/09 15:44:31 INFO MapOutputTrackerMasterEndpoint: MapOutputTrackerMasterEndpoint stopped!
[2025-10-09T15:44:31.197+0000] {subprocess.py:93} INFO - 25/10/09 15:44:31 INFO MemoryStore: MemoryStore cleared
[2025-10-09T15:44:31.199+0000] {subprocess.py:93} INFO - 25/10/09 15:44:31 INFO BlockManager: BlockManager stopped
[2025-10-09T15:44:31.222+0000] {subprocess.py:93} INFO - 25/10/09 15:44:31 INFO BlockManagerMaster: BlockManagerMaster stopped
[2025-10-09T15:44:31.232+0000] {subprocess.py:93} INFO - 25/10/09 15:44:31 INFO OutputCommitCoordinator$OutputCommitCoordinatorEndpoint: OutputCommitCoordinator stopped!
[2025-10-09T15:44:31.268+0000] {subprocess.py:93} INFO - 25/10/09 15:44:31 INFO SparkContext: Successfully stopped SparkContext
[2025-10-09T15:44:31.275+0000] {subprocess.py:93} INFO - 25/10/09 15:44:31 INFO ShutdownHookManager: Shutdown hook called
[2025-10-09T15:44:31.279+0000] {subprocess.py:93} INFO - 25/10/09 15:44:31 INFO ShutdownHookManager: Deleting directory /tmp/spark-9b747f51-2c75-4bce-bc51-7c1497a89d7c
[2025-10-09T15:44:31.289+0000] {subprocess.py:93} INFO - 25/10/09 15:44:31 INFO ShutdownHookManager: Deleting directory /tmp/spark-9b747f51-2c75-4bce-bc51-7c1497a89d7c/pyspark-d286e5b1-a9ed-4e00-ae78-630567802a27
[2025-10-09T15:44:31.299+0000] {subprocess.py:93} INFO - 25/10/09 15:44:31 INFO ShutdownHookManager: Deleting directory /tmp/spark-ab15d85f-629f-4a01-8167-f0574840dc02
[2025-10-09T15:44:31.422+0000] {subprocess.py:97} INFO - Command exited with return code 1
[2025-10-09T15:44:31.426+0000] {taskinstance.py:441} INFO - ::group::Post task execution logs
[2025-10-09T15:44:31.458+0000] {taskinstance.py:2905} ERROR - Task failed with exception
Traceback (most recent call last):
  File "/home/airflow/.local/lib/python3.12/site-packages/airflow/models/taskinstance.py", line 465, in _execute_task
    result = _execute_callable(context=context, **execute_callable_kwargs)
             ^^^^^^^^^^^^^^^^^^^^^^^^^^^^^^^^^^^^^^^^^^^^^^^^^^^^^^^^^^^^^
  File "/home/airflow/.local/lib/python3.12/site-packages/airflow/models/taskinstance.py", line 432, in _execute_callable
    return execute_callable(context=context, **execute_callable_kwargs)
           ^^^^^^^^^^^^^^^^^^^^^^^^^^^^^^^^^^^^^^^^^^^^^^^^^^^^^^^^^^^^
  File "/home/airflow/.local/lib/python3.12/site-packages/airflow/models/baseoperator.py", line 401, in wrapper
    return func(self, *args, **kwargs)
           ^^^^^^^^^^^^^^^^^^^^^^^^^^^
  File "/home/airflow/.local/lib/python3.12/site-packages/airflow/operators/bash.py", line 243, in execute
    raise AirflowException(
airflow.exceptions.AirflowException: Bash command failed. The command returned a non-zero exit code 1.
[2025-10-09T15:44:31.477+0000] {taskinstance.py:1206} INFO - Marking task as UP_FOR_RETRY. dag_id=restaurant_analytics, task_id=retrain_model, run_id=manual__2025-10-09T15:43:30.208014+00:00, execution_date=20251009T154330, start_date=20251009T154352, end_date=20251009T154431
[2025-10-09T15:44:31.529+0000] {warnings.py:112} WARNING - /home/***/.local/lib/python3.12/site-packages/***/utils/email.py:154: RemovedInAirflow3Warning: Fetching SMTP credentials from configuration variables will be deprecated in a future release. Please set credentials using a connection instead.
  send_mime_email(e_from=mail_from, e_to=recipients, mime_msg=msg, conn_id=conn_id, dryrun=dryrun)

[2025-10-09T15:44:31.532+0000] {configuration.py:1053} WARNING - section/key [smtp/smtp_user] not found in config
[2025-10-09T15:44:31.535+0000] {email.py:271} INFO - Email alerting: attempt 1
[2025-10-09T15:44:31.568+0000] {configuration.py:1053} WARNING - section/key [smtp/smtp_user] not found in config
[2025-10-09T15:44:31.572+0000] {email.py:271} INFO - Email alerting: attempt 1
[2025-10-09T15:44:31.575+0000] {taskinstance.py:879} ERROR - Failed to send email to: ['quantruong1918@gmail.com']
Traceback (most recent call last):
  File "/home/airflow/.local/lib/python3.12/site-packages/airflow/models/taskinstance.py", line 2479, in _run_raw_task
    self._execute_task_with_callbacks(context, test_mode, session=session)
  File "/home/airflow/.local/lib/python3.12/site-packages/airflow/models/taskinstance.py", line 2676, in _execute_task_with_callbacks
    result = self._execute_task(context, task_orig)
             ^^^^^^^^^^^^^^^^^^^^^^^^^^^^^^^^^^^^^^
  File "/home/airflow/.local/lib/python3.12/site-packages/airflow/models/taskinstance.py", line 2701, in _execute_task
    return _execute_task(self, context, task_orig)
           ^^^^^^^^^^^^^^^^^^^^^^^^^^^^^^^^^^^^^^^
  File "/home/airflow/.local/lib/python3.12/site-packages/airflow/models/taskinstance.py", line 465, in _execute_task
    result = _execute_callable(context=context, **execute_callable_kwargs)
             ^^^^^^^^^^^^^^^^^^^^^^^^^^^^^^^^^^^^^^^^^^^^^^^^^^^^^^^^^^^^^
  File "/home/airflow/.local/lib/python3.12/site-packages/airflow/models/taskinstance.py", line 432, in _execute_callable
    return execute_callable(context=context, **execute_callable_kwargs)
           ^^^^^^^^^^^^^^^^^^^^^^^^^^^^^^^^^^^^^^^^^^^^^^^^^^^^^^^^^^^^
  File "/home/airflow/.local/lib/python3.12/site-packages/airflow/models/baseoperator.py", line 401, in wrapper
    return func(self, *args, **kwargs)
           ^^^^^^^^^^^^^^^^^^^^^^^^^^^
  File "/home/airflow/.local/lib/python3.12/site-packages/airflow/operators/bash.py", line 243, in execute
    raise AirflowException(
airflow.exceptions.AirflowException: Bash command failed. The command returned a non-zero exit code 1.

During handling of the above exception, another exception occurred:

Traceback (most recent call last):
  File "/home/airflow/.local/lib/python3.12/site-packages/airflow/models/taskinstance.py", line 1063, in _email_alert
    send_email(task.email, subject, html_content)
  File "/home/airflow/.local/lib/python3.12/site-packages/airflow/utils/email.py", line 80, in send_email
    return backend(
           ^^^^^^^^
  File "/home/airflow/.local/lib/python3.12/site-packages/airflow/utils/email.py", line 154, in send_email_smtp
    send_mime_email(e_from=mail_from, e_to=recipients, mime_msg=msg, conn_id=conn_id, dryrun=dryrun)
  File "/home/airflow/.local/lib/python3.12/site-packages/airflow/utils/email.py", line 273, in send_mime_email
    smtp_conn = _get_smtp_connection(smtp_host, smtp_port, smtp_timeout, smtp_ssl)
                ^^^^^^^^^^^^^^^^^^^^^^^^^^^^^^^^^^^^^^^^^^^^^^^^^^^^^^^^^^^^^^^^^^
  File "/home/airflow/.local/lib/python3.12/site-packages/airflow/utils/email.py", line 317, in _get_smtp_connection
    return smtplib.SMTP(host=host, port=port, timeout=timeout)
           ^^^^^^^^^^^^^^^^^^^^^^^^^^^^^^^^^^^^^^^^^^^^^^^^^^^
  File "/usr/local/lib/python3.12/smtplib.py", line 255, in __init__
    (code, msg) = self.connect(host, port)
                  ^^^^^^^^^^^^^^^^^^^^^^^^
  File "/usr/local/lib/python3.12/smtplib.py", line 341, in connect
    self.sock = self._get_socket(host, port, self.timeout)
                ^^^^^^^^^^^^^^^^^^^^^^^^^^^^^^^^^^^^^^^^^^
  File "/usr/local/lib/python3.12/smtplib.py", line 312, in _get_socket
    return socket.create_connection((host, port), timeout,
           ^^^^^^^^^^^^^^^^^^^^^^^^^^^^^^^^^^^^^^^^^^^^^^^
  File "/usr/local/lib/python3.12/socket.py", line 853, in create_connection
    raise exceptions[0]
  File "/usr/local/lib/python3.12/socket.py", line 838, in create_connection
    sock.connect(sa)
ConnectionRefusedError: [Errno 111] Connection refused

During handling of the above exception, another exception occurred:

Traceback (most recent call last):
  File "/home/airflow/.local/lib/python3.12/site-packages/airflow/models/taskinstance.py", line 877, in _handle_failure
    task_instance.email_alert(error, failure_context["task"])
  File "/home/airflow/.local/lib/python3.12/site-packages/airflow/models/taskinstance.py", line 3163, in email_alert
    _email_alert(task_instance=self, exception=exception, task=task)
  File "/home/airflow/.local/lib/python3.12/site-packages/airflow/models/taskinstance.py", line 1065, in _email_alert
    send_email(task.email, subject, html_content_err)
  File "/home/airflow/.local/lib/python3.12/site-packages/airflow/utils/email.py", line 80, in send_email
    return backend(
           ^^^^^^^^
  File "/home/airflow/.local/lib/python3.12/site-packages/airflow/utils/email.py", line 154, in send_email_smtp
    send_mime_email(e_from=mail_from, e_to=recipients, mime_msg=msg, conn_id=conn_id, dryrun=dryrun)
  File "/home/airflow/.local/lib/python3.12/site-packages/airflow/utils/email.py", line 273, in send_mime_email
    smtp_conn = _get_smtp_connection(smtp_host, smtp_port, smtp_timeout, smtp_ssl)
                ^^^^^^^^^^^^^^^^^^^^^^^^^^^^^^^^^^^^^^^^^^^^^^^^^^^^^^^^^^^^^^^^^^
  File "/home/airflow/.local/lib/python3.12/site-packages/airflow/utils/email.py", line 317, in _get_smtp_connection
    return smtplib.SMTP(host=host, port=port, timeout=timeout)
           ^^^^^^^^^^^^^^^^^^^^^^^^^^^^^^^^^^^^^^^^^^^^^^^^^^^
  File "/usr/local/lib/python3.12/smtplib.py", line 255, in __init__
    (code, msg) = self.connect(host, port)
                  ^^^^^^^^^^^^^^^^^^^^^^^^
  File "/usr/local/lib/python3.12/smtplib.py", line 341, in connect
    self.sock = self._get_socket(host, port, self.timeout)
                ^^^^^^^^^^^^^^^^^^^^^^^^^^^^^^^^^^^^^^^^^^
  File "/usr/local/lib/python3.12/smtplib.py", line 312, in _get_socket
    return socket.create_connection((host, port), timeout,
           ^^^^^^^^^^^^^^^^^^^^^^^^^^^^^^^^^^^^^^^^^^^^^^^
  File "/usr/local/lib/python3.12/socket.py", line 853, in create_connection
    raise exceptions[0]
  File "/usr/local/lib/python3.12/socket.py", line 838, in create_connection
    sock.connect(sa)
ConnectionRefusedError: [Errno 111] Connection refused
[2025-10-09T15:44:31.639+0000] {standard_task_runner.py:110} ERROR - Failed to execute job 271 for task retrain_model (Bash command failed. The command returned a non-zero exit code 1.; 3526)
[2025-10-09T15:44:31.720+0000] {local_task_job_runner.py:243} INFO - Task exited with return code 1
[2025-10-09T15:44:31.819+0000] {taskinstance.py:3503} INFO - 0 downstream tasks scheduled from follow-on schedule check
[2025-10-09T15:44:31.844+0000] {local_task_job_runner.py:222} INFO - ::endgroup::
