[2025-10-08T06:00:03.827+0000] {local_task_job_runner.py:120} INFO - ::group::Pre task execution logs
[2025-10-08T06:00:03.876+0000] {taskinstance.py:2076} INFO - Dependencies all met for dep_context=non-requeueable deps ti=<TaskInstance: restaurant_analytics.retrain_model scheduled__2025-10-08T05:00:00+00:00 [queued]>
[2025-10-08T06:00:03.892+0000] {taskinstance.py:2076} INFO - Dependencies all met for dep_context=requeueable deps ti=<TaskInstance: restaurant_analytics.retrain_model scheduled__2025-10-08T05:00:00+00:00 [queued]>
[2025-10-08T06:00:03.902+0000] {taskinstance.py:2306} INFO - Starting attempt 1 of 2
[2025-10-08T06:00:03.928+0000] {taskinstance.py:2330} INFO - Executing <Task(BashOperator): retrain_model> on 2025-10-08 05:00:00+00:00
[2025-10-08T06:00:03.942+0000] {warnings.py:112} WARNING - /home/***/.local/lib/python3.12/site-packages/***/task/task_runner/standard_task_runner.py:62: DeprecationWarning: This process (pid=264) is multi-threaded, use of fork() may lead to deadlocks in the child.
  pid = os.fork()

[2025-10-08T06:00:03.945+0000] {standard_task_runner.py:64} INFO - Started process 268 to run task
[2025-10-08T06:00:03.947+0000] {standard_task_runner.py:90} INFO - Running: ['***', 'tasks', 'run', 'restaurant_analytics', 'retrain_model', 'scheduled__2025-10-08T05:00:00+00:00', '--job-id', '147', '--raw', '--subdir', 'DAGS_FOLDER/restaurant_dag.py', '--cfg-path', '/tmp/tmp1gvx5u85']
[2025-10-08T06:00:03.953+0000] {standard_task_runner.py:91} INFO - Job 147: Subtask retrain_model
[2025-10-08T06:00:04.092+0000] {task_command.py:426} INFO - Running <TaskInstance: restaurant_analytics.retrain_model scheduled__2025-10-08T05:00:00+00:00 [running]> on host c34aac175a74
[2025-10-08T06:00:04.386+0000] {taskinstance.py:2648} INFO - Exporting env vars: AIRFLOW_CTX_DAG_EMAIL='quantruong1918@gmail.com' AIRFLOW_CTX_DAG_OWNER='***' AIRFLOW_CTX_DAG_ID='restaurant_analytics' AIRFLOW_CTX_TASK_ID='retrain_model' AIRFLOW_CTX_EXECUTION_DATE='2025-10-08T05:00:00+00:00' AIRFLOW_CTX_TRY_NUMBER='1' AIRFLOW_CTX_DAG_RUN_ID='scheduled__2025-10-08T05:00:00+00:00'
[2025-10-08T06:00:04.390+0000] {taskinstance.py:430} INFO - ::endgroup::
[2025-10-08T06:00:04.395+0000] {subprocess.py:63} INFO - Tmp dir root location: /tmp
[2025-10-08T06:00:04.399+0000] {subprocess.py:75} INFO - Running command: ['/usr/bin/bash', '-c', '/opt/spark/bin/spark-submit --master local[*] /opt/***/dags/train_lr.py']
[2025-10-08T06:00:04.434+0000] {subprocess.py:86} INFO - Output:
[2025-10-08T06:00:12.726+0000] {subprocess.py:93} INFO - Traceback (most recent call last):
[2025-10-08T06:00:12.727+0000] {subprocess.py:93} INFO -   File "/opt/***/dags/train_lr.py", line 2, in <module>
[2025-10-08T06:00:12.733+0000] {subprocess.py:93} INFO -     from pyspark.ml.feature import VectorAssembler
[2025-10-08T06:00:12.734+0000] {subprocess.py:93} INFO -   File "/opt/spark/python/lib/pyspark.zip/pyspark/ml/__init__.py", line 22, in <module>
[2025-10-08T06:00:12.735+0000] {subprocess.py:93} INFO -   File "/opt/spark/python/lib/pyspark.zip/pyspark/ml/base.py", line 40, in <module>
[2025-10-08T06:00:12.736+0000] {subprocess.py:93} INFO -   File "/opt/spark/python/lib/pyspark.zip/pyspark/ml/param/__init__.py", line 32, in <module>
[2025-10-08T06:00:12.739+0000] {subprocess.py:93} INFO - ModuleNotFoundError: No module named 'numpy'
[2025-10-08T06:00:12.846+0000] {subprocess.py:93} INFO - 25/10/08 06:00:12 INFO ShutdownHookManager: Shutdown hook called
[2025-10-08T06:00:12.853+0000] {subprocess.py:93} INFO - 25/10/08 06:00:12 INFO ShutdownHookManager: Deleting directory /tmp/spark-c3decdeb-fc33-4af2-b2b1-12fbb5702f94
[2025-10-08T06:00:12.930+0000] {subprocess.py:97} INFO - Command exited with return code 1
[2025-10-08T06:00:12.931+0000] {taskinstance.py:441} INFO - ::group::Post task execution logs
[2025-10-08T06:00:12.955+0000] {taskinstance.py:2905} ERROR - Task failed with exception
Traceback (most recent call last):
  File "/home/airflow/.local/lib/python3.12/site-packages/airflow/models/taskinstance.py", line 465, in _execute_task
    result = _execute_callable(context=context, **execute_callable_kwargs)
             ^^^^^^^^^^^^^^^^^^^^^^^^^^^^^^^^^^^^^^^^^^^^^^^^^^^^^^^^^^^^^
  File "/home/airflow/.local/lib/python3.12/site-packages/airflow/models/taskinstance.py", line 432, in _execute_callable
    return execute_callable(context=context, **execute_callable_kwargs)
           ^^^^^^^^^^^^^^^^^^^^^^^^^^^^^^^^^^^^^^^^^^^^^^^^^^^^^^^^^^^^
  File "/home/airflow/.local/lib/python3.12/site-packages/airflow/models/baseoperator.py", line 401, in wrapper
    return func(self, *args, **kwargs)
           ^^^^^^^^^^^^^^^^^^^^^^^^^^^
  File "/home/airflow/.local/lib/python3.12/site-packages/airflow/operators/bash.py", line 243, in execute
    raise AirflowException(
airflow.exceptions.AirflowException: Bash command failed. The command returned a non-zero exit code 1.
[2025-10-08T06:00:12.968+0000] {taskinstance.py:1206} INFO - Marking task as UP_FOR_RETRY. dag_id=restaurant_analytics, task_id=retrain_model, run_id=scheduled__2025-10-08T05:00:00+00:00, execution_date=20251008T050000, start_date=20251008T060003, end_date=20251008T060012
[2025-10-08T06:00:13.012+0000] {warnings.py:112} WARNING - /home/***/.local/lib/python3.12/site-packages/***/utils/email.py:154: RemovedInAirflow3Warning: Fetching SMTP credentials from configuration variables will be deprecated in a future release. Please set credentials using a connection instead.
  send_mime_email(e_from=mail_from, e_to=recipients, mime_msg=msg, conn_id=conn_id, dryrun=dryrun)

[2025-10-08T06:00:13.014+0000] {configuration.py:1053} WARNING - section/key [smtp/smtp_user] not found in config
[2025-10-08T06:00:13.015+0000] {email.py:271} INFO - Email alerting: attempt 1
[2025-10-08T06:00:13.033+0000] {configuration.py:1053} WARNING - section/key [smtp/smtp_user] not found in config
[2025-10-08T06:00:13.039+0000] {email.py:271} INFO - Email alerting: attempt 1
[2025-10-08T06:00:13.041+0000] {taskinstance.py:879} ERROR - Failed to send email to: ['quantruong1918@gmail.com']
Traceback (most recent call last):
  File "/home/airflow/.local/lib/python3.12/site-packages/airflow/models/taskinstance.py", line 2479, in _run_raw_task
    self._execute_task_with_callbacks(context, test_mode, session=session)
  File "/home/airflow/.local/lib/python3.12/site-packages/airflow/models/taskinstance.py", line 2676, in _execute_task_with_callbacks
    result = self._execute_task(context, task_orig)
             ^^^^^^^^^^^^^^^^^^^^^^^^^^^^^^^^^^^^^^
  File "/home/airflow/.local/lib/python3.12/site-packages/airflow/models/taskinstance.py", line 2701, in _execute_task
    return _execute_task(self, context, task_orig)
           ^^^^^^^^^^^^^^^^^^^^^^^^^^^^^^^^^^^^^^^
  File "/home/airflow/.local/lib/python3.12/site-packages/airflow/models/taskinstance.py", line 465, in _execute_task
    result = _execute_callable(context=context, **execute_callable_kwargs)
             ^^^^^^^^^^^^^^^^^^^^^^^^^^^^^^^^^^^^^^^^^^^^^^^^^^^^^^^^^^^^^
  File "/home/airflow/.local/lib/python3.12/site-packages/airflow/models/taskinstance.py", line 432, in _execute_callable
    return execute_callable(context=context, **execute_callable_kwargs)
           ^^^^^^^^^^^^^^^^^^^^^^^^^^^^^^^^^^^^^^^^^^^^^^^^^^^^^^^^^^^^
  File "/home/airflow/.local/lib/python3.12/site-packages/airflow/models/baseoperator.py", line 401, in wrapper
    return func(self, *args, **kwargs)
           ^^^^^^^^^^^^^^^^^^^^^^^^^^^
  File "/home/airflow/.local/lib/python3.12/site-packages/airflow/operators/bash.py", line 243, in execute
    raise AirflowException(
airflow.exceptions.AirflowException: Bash command failed. The command returned a non-zero exit code 1.

During handling of the above exception, another exception occurred:

Traceback (most recent call last):
  File "/home/airflow/.local/lib/python3.12/site-packages/airflow/models/taskinstance.py", line 1063, in _email_alert
    send_email(task.email, subject, html_content)
  File "/home/airflow/.local/lib/python3.12/site-packages/airflow/utils/email.py", line 80, in send_email
    return backend(
           ^^^^^^^^
  File "/home/airflow/.local/lib/python3.12/site-packages/airflow/utils/email.py", line 154, in send_email_smtp
    send_mime_email(e_from=mail_from, e_to=recipients, mime_msg=msg, conn_id=conn_id, dryrun=dryrun)
  File "/home/airflow/.local/lib/python3.12/site-packages/airflow/utils/email.py", line 273, in send_mime_email
    smtp_conn = _get_smtp_connection(smtp_host, smtp_port, smtp_timeout, smtp_ssl)
                ^^^^^^^^^^^^^^^^^^^^^^^^^^^^^^^^^^^^^^^^^^^^^^^^^^^^^^^^^^^^^^^^^^
  File "/home/airflow/.local/lib/python3.12/site-packages/airflow/utils/email.py", line 317, in _get_smtp_connection
    return smtplib.SMTP(host=host, port=port, timeout=timeout)
           ^^^^^^^^^^^^^^^^^^^^^^^^^^^^^^^^^^^^^^^^^^^^^^^^^^^
  File "/usr/local/lib/python3.12/smtplib.py", line 255, in __init__
    (code, msg) = self.connect(host, port)
                  ^^^^^^^^^^^^^^^^^^^^^^^^
  File "/usr/local/lib/python3.12/smtplib.py", line 341, in connect
    self.sock = self._get_socket(host, port, self.timeout)
                ^^^^^^^^^^^^^^^^^^^^^^^^^^^^^^^^^^^^^^^^^^
  File "/usr/local/lib/python3.12/smtplib.py", line 312, in _get_socket
    return socket.create_connection((host, port), timeout,
           ^^^^^^^^^^^^^^^^^^^^^^^^^^^^^^^^^^^^^^^^^^^^^^^
  File "/usr/local/lib/python3.12/socket.py", line 853, in create_connection
    raise exceptions[0]
  File "/usr/local/lib/python3.12/socket.py", line 838, in create_connection
    sock.connect(sa)
ConnectionRefusedError: [Errno 111] Connection refused

During handling of the above exception, another exception occurred:

Traceback (most recent call last):
  File "/home/airflow/.local/lib/python3.12/site-packages/airflow/models/taskinstance.py", line 877, in _handle_failure
    task_instance.email_alert(error, failure_context["task"])
  File "/home/airflow/.local/lib/python3.12/site-packages/airflow/models/taskinstance.py", line 3163, in email_alert
    _email_alert(task_instance=self, exception=exception, task=task)
  File "/home/airflow/.local/lib/python3.12/site-packages/airflow/models/taskinstance.py", line 1065, in _email_alert
    send_email(task.email, subject, html_content_err)
  File "/home/airflow/.local/lib/python3.12/site-packages/airflow/utils/email.py", line 80, in send_email
    return backend(
           ^^^^^^^^
  File "/home/airflow/.local/lib/python3.12/site-packages/airflow/utils/email.py", line 154, in send_email_smtp
    send_mime_email(e_from=mail_from, e_to=recipients, mime_msg=msg, conn_id=conn_id, dryrun=dryrun)
  File "/home/airflow/.local/lib/python3.12/site-packages/airflow/utils/email.py", line 273, in send_mime_email
    smtp_conn = _get_smtp_connection(smtp_host, smtp_port, smtp_timeout, smtp_ssl)
                ^^^^^^^^^^^^^^^^^^^^^^^^^^^^^^^^^^^^^^^^^^^^^^^^^^^^^^^^^^^^^^^^^^
  File "/home/airflow/.local/lib/python3.12/site-packages/airflow/utils/email.py", line 317, in _get_smtp_connection
    return smtplib.SMTP(host=host, port=port, timeout=timeout)
           ^^^^^^^^^^^^^^^^^^^^^^^^^^^^^^^^^^^^^^^^^^^^^^^^^^^
  File "/usr/local/lib/python3.12/smtplib.py", line 255, in __init__
    (code, msg) = self.connect(host, port)
                  ^^^^^^^^^^^^^^^^^^^^^^^^
  File "/usr/local/lib/python3.12/smtplib.py", line 341, in connect
    self.sock = self._get_socket(host, port, self.timeout)
                ^^^^^^^^^^^^^^^^^^^^^^^^^^^^^^^^^^^^^^^^^^
  File "/usr/local/lib/python3.12/smtplib.py", line 312, in _get_socket
    return socket.create_connection((host, port), timeout,
           ^^^^^^^^^^^^^^^^^^^^^^^^^^^^^^^^^^^^^^^^^^^^^^^
  File "/usr/local/lib/python3.12/socket.py", line 853, in create_connection
    raise exceptions[0]
  File "/usr/local/lib/python3.12/socket.py", line 838, in create_connection
    sock.connect(sa)
ConnectionRefusedError: [Errno 111] Connection refused
[2025-10-08T06:00:13.082+0000] {standard_task_runner.py:110} ERROR - Failed to execute job 147 for task retrain_model (Bash command failed. The command returned a non-zero exit code 1.; 268)
[2025-10-08T06:00:13.153+0000] {local_task_job_runner.py:243} INFO - Task exited with return code 1
[2025-10-08T06:00:13.185+0000] {taskinstance.py:3503} INFO - 0 downstream tasks scheduled from follow-on schedule check
[2025-10-08T06:00:13.198+0000] {local_task_job_runner.py:222} INFO - ::endgroup::
