[2025-10-09T01:48:23.338+0000] {local_task_job_runner.py:120} INFO - ::group::Pre task execution logs
[2025-10-09T01:48:23.496+0000] {taskinstance.py:2076} INFO - Dependencies all met for dep_context=non-requeueable deps ti=<TaskInstance: restaurant_analytics.run_spark_stream scheduled__2025-10-09T00:00:00+00:00 [queued]>
[2025-10-09T01:48:23.538+0000] {taskinstance.py:2076} INFO - Dependencies all met for dep_context=requeueable deps ti=<TaskInstance: restaurant_analytics.run_spark_stream scheduled__2025-10-09T00:00:00+00:00 [queued]>
[2025-10-09T01:48:23.540+0000] {taskinstance.py:2306} INFO - Starting attempt 1 of 2
[2025-10-09T01:48:23.653+0000] {taskinstance.py:2330} INFO - Executing <Task(BashOperator): run_spark_stream> on 2025-10-09 00:00:00+00:00
[2025-10-09T01:48:23.694+0000] {warnings.py:112} WARNING - /home/***/.local/lib/python3.12/site-packages/***/task/task_runner/standard_task_runner.py:62: DeprecationWarning: This process (pid=89) is multi-threaded, use of fork() may lead to deadlocks in the child.
  pid = os.fork()

[2025-10-09T01:48:23.706+0000] {standard_task_runner.py:64} INFO - Started process 101 to run task
[2025-10-09T01:48:23.706+0000] {standard_task_runner.py:90} INFO - Running: ['***', 'tasks', 'run', 'restaurant_analytics', 'run_spark_stream', 'scheduled__2025-10-09T00:00:00+00:00', '--job-id', '231', '--raw', '--subdir', 'DAGS_FOLDER/restaurant_dag.py', '--cfg-path', '/tmp/tmpywiuo2j9']
[2025-10-09T01:48:23.713+0000] {standard_task_runner.py:91} INFO - Job 231: Subtask run_spark_stream
[2025-10-09T01:48:24.107+0000] {task_command.py:426} INFO - Running <TaskInstance: restaurant_analytics.run_spark_stream scheduled__2025-10-09T00:00:00+00:00 [running]> on host 80bac2d65317
[2025-10-09T01:48:25.005+0000] {taskinstance.py:2648} INFO - Exporting env vars: AIRFLOW_CTX_DAG_EMAIL='quantruong1918@gmail.com' AIRFLOW_CTX_DAG_OWNER='***' AIRFLOW_CTX_DAG_ID='restaurant_analytics' AIRFLOW_CTX_TASK_ID='run_spark_stream' AIRFLOW_CTX_EXECUTION_DATE='2025-10-09T00:00:00+00:00' AIRFLOW_CTX_TRY_NUMBER='1' AIRFLOW_CTX_DAG_RUN_ID='scheduled__2025-10-09T00:00:00+00:00'
[2025-10-09T01:48:25.018+0000] {taskinstance.py:430} INFO - ::endgroup::
[2025-10-09T01:48:25.020+0000] {subprocess.py:63} INFO - Tmp dir root location: /tmp
[2025-10-09T01:48:25.025+0000] {subprocess.py:75} INFO - Running command: ['/usr/bin/bash', '-c', 'export PYSPARK_PYTHON=/usr/local/bin/python && export PYSPARK_DRIVER_PYTHON=/usr/local/bin/python && /opt/spark/bin/spark-submit --master local[*] --packages org.apache.spark:spark-sql-kafka-0-10_2.12:3.5.1 /opt/***/dags/spark_streaming.py']
[2025-10-09T01:48:25.103+0000] {subprocess.py:86} INFO - Output:
[2025-10-09T01:48:38.288+0000] {subprocess.py:93} INFO - :: loading settings :: url = jar:file:/opt/spark/jars/ivy-2.5.1.jar!/org/apache/ivy/core/settings/ivysettings.xml
[2025-10-09T01:48:38.538+0000] {subprocess.py:93} INFO - Ivy Default Cache set to: /home/***/.ivy2/cache
[2025-10-09T01:48:38.539+0000] {subprocess.py:93} INFO - The jars for the packages stored in: /home/***/.ivy2/jars
[2025-10-09T01:48:38.552+0000] {subprocess.py:93} INFO - org.apache.spark#spark-sql-kafka-0-10_2.12 added as a dependency
[2025-10-09T01:48:38.558+0000] {subprocess.py:93} INFO - :: resolving dependencies :: org.apache.spark#spark-submit-parent-f06a8393-3715-4349-a4e5-d8c756883530;1.0
[2025-10-09T01:48:38.560+0000] {subprocess.py:93} INFO - 	confs: [default]
[2025-10-09T01:48:44.067+0000] {subprocess.py:93} INFO - :: resolution report :: resolve 5510ms :: artifacts dl 0ms
[2025-10-09T01:48:44.069+0000] {subprocess.py:93} INFO - 	:: modules in use:
[2025-10-09T01:48:44.074+0000] {subprocess.py:93} INFO - 	---------------------------------------------------------------------
[2025-10-09T01:48:44.076+0000] {subprocess.py:93} INFO - 	|                  |            modules            ||   artifacts   |
[2025-10-09T01:48:44.079+0000] {subprocess.py:93} INFO - 	|       conf       | number| search|dwnlded|evicted|| number|dwnlded|
[2025-10-09T01:48:44.080+0000] {subprocess.py:93} INFO - 	---------------------------------------------------------------------
[2025-10-09T01:48:44.081+0000] {subprocess.py:93} INFO - 	|      default     |   1   |   0   |   0   |   0   ||   0   |   0   |
[2025-10-09T01:48:44.088+0000] {subprocess.py:93} INFO - 	---------------------------------------------------------------------
[2025-10-09T01:48:44.089+0000] {subprocess.py:93} INFO - 
[2025-10-09T01:48:44.090+0000] {subprocess.py:93} INFO - :: problems summary ::
[2025-10-09T01:48:44.091+0000] {subprocess.py:93} INFO - :::: WARNINGS
[2025-10-09T01:48:44.092+0000] {subprocess.py:93} INFO - 	problem while downloading module descriptor: https://repo1.maven.org/maven2/org/apache/spark/spark-parent_2.12/3.5.1/spark-parent_2.12-3.5.1.pom: impossible to move part file to definitive one: /home/***/.ivy2/cache/org.apache.spark/spark-parent_2.12/ivy-3.5.1.xml.original.part -> /home/***/.ivy2/cache/org.apache.spark/spark-parent_2.12/ivy-3.5.1.xml.original (126ms)
[2025-10-09T01:48:44.093+0000] {subprocess.py:93} INFO - 
[2025-10-09T01:48:44.094+0000] {subprocess.py:93} INFO - 	io problem while parsing ivy file: https://repo1.maven.org/maven2/org/apache/spark/spark-sql-kafka-0-10_2.12/3.5.1/spark-sql-kafka-0-10_2.12-3.5.1.pom (java.io.IOException: Impossible to load parent for file:/home/***/.ivy2/cache/org.apache.spark/spark-sql-kafka-0-10_2.12/ivy-3.5.1.xml.original. Parent=org.apache.spark#spark-parent_2.12;3.5.1)
[2025-10-09T01:48:44.095+0000] {subprocess.py:93} INFO - 
[2025-10-09T01:48:44.096+0000] {subprocess.py:93} INFO - 		module not found: org.apache.spark#spark-sql-kafka-0-10_2.12;3.5.1
[2025-10-09T01:48:44.097+0000] {subprocess.py:93} INFO - 
[2025-10-09T01:48:44.098+0000] {subprocess.py:93} INFO - 	==== local-m2-cache: tried
[2025-10-09T01:48:44.098+0000] {subprocess.py:93} INFO - 
[2025-10-09T01:48:44.100+0000] {subprocess.py:93} INFO - 	  file:/home/***/.m2/repository/org/apache/spark/spark-parent_2.12/3.5.1/spark-parent_2.12-3.5.1.pom
[2025-10-09T01:48:44.101+0000] {subprocess.py:93} INFO - 
[2025-10-09T01:48:44.102+0000] {subprocess.py:93} INFO - 	  -- artifact org.apache.spark#spark-parent_2.12;3.5.1!spark-parent_2.12.jar:
[2025-10-09T01:48:44.103+0000] {subprocess.py:93} INFO - 
[2025-10-09T01:48:44.105+0000] {subprocess.py:93} INFO - 	  file:/home/***/.m2/repository/org/apache/spark/spark-parent_2.12/3.5.1/spark-parent_2.12-3.5.1.jar
[2025-10-09T01:48:44.106+0000] {subprocess.py:93} INFO - 
[2025-10-09T01:48:44.107+0000] {subprocess.py:93} INFO - 	==== local-ivy-cache: tried
[2025-10-09T01:48:44.108+0000] {subprocess.py:93} INFO - 
[2025-10-09T01:48:44.110+0000] {subprocess.py:93} INFO - 	  /home/***/.ivy2/local/org.apache.spark/spark-parent_2.12/3.5.1/ivys/ivy.xml
[2025-10-09T01:48:44.111+0000] {subprocess.py:93} INFO - 
[2025-10-09T01:48:44.111+0000] {subprocess.py:93} INFO - 	  -- artifact org.apache.spark#spark-parent_2.12;3.5.1!spark-parent_2.12.jar:
[2025-10-09T01:48:44.112+0000] {subprocess.py:93} INFO - 
[2025-10-09T01:48:44.113+0000] {subprocess.py:93} INFO - 	  /home/***/.ivy2/local/org.apache.spark/spark-parent_2.12/3.5.1/jars/spark-parent_2.12.jar
[2025-10-09T01:48:44.114+0000] {subprocess.py:93} INFO - 
[2025-10-09T01:48:44.114+0000] {subprocess.py:93} INFO - 	==== central: tried
[2025-10-09T01:48:44.115+0000] {subprocess.py:93} INFO - 
[2025-10-09T01:48:44.116+0000] {subprocess.py:93} INFO - 	  https://repo1.maven.org/maven2/org/apache/spark/spark-parent_2.12/3.5.1/spark-parent_2.12-3.5.1.pom
[2025-10-09T01:48:44.117+0000] {subprocess.py:93} INFO - 
[2025-10-09T01:48:44.118+0000] {subprocess.py:93} INFO - 	==== spark-packages: tried
[2025-10-09T01:48:44.119+0000] {subprocess.py:93} INFO - 
[2025-10-09T01:48:44.120+0000] {subprocess.py:93} INFO - 	  https://repos.spark-packages.org/org/apache/spark/spark-sql-kafka-0-10_2.12/3.5.1/spark-sql-kafka-0-10_2.12-3.5.1.pom
[2025-10-09T01:48:44.121+0000] {subprocess.py:93} INFO - 
[2025-10-09T01:48:44.122+0000] {subprocess.py:93} INFO - 	  -- artifact org.apache.spark#spark-sql-kafka-0-10_2.12;3.5.1!spark-sql-kafka-0-10_2.12.jar:
[2025-10-09T01:48:44.123+0000] {subprocess.py:93} INFO - 
[2025-10-09T01:48:44.124+0000] {subprocess.py:93} INFO - 	  https://repos.spark-packages.org/org/apache/spark/spark-sql-kafka-0-10_2.12/3.5.1/spark-sql-kafka-0-10_2.12-3.5.1.jar
[2025-10-09T01:48:44.124+0000] {subprocess.py:93} INFO - 
[2025-10-09T01:48:44.125+0000] {subprocess.py:93} INFO - 		::::::::::::::::::::::::::::::::::::::::::::::
[2025-10-09T01:48:44.126+0000] {subprocess.py:93} INFO - 
[2025-10-09T01:48:44.127+0000] {subprocess.py:93} INFO - 		::          UNRESOLVED DEPENDENCIES         ::
[2025-10-09T01:48:44.128+0000] {subprocess.py:93} INFO - 
[2025-10-09T01:48:44.128+0000] {subprocess.py:93} INFO - 		::::::::::::::::::::::::::::::::::::::::::::::
[2025-10-09T01:48:44.129+0000] {subprocess.py:93} INFO - 
[2025-10-09T01:48:44.130+0000] {subprocess.py:93} INFO - 		:: org.apache.spark#spark-sql-kafka-0-10_2.12;3.5.1: not found
[2025-10-09T01:48:44.131+0000] {subprocess.py:93} INFO - 
[2025-10-09T01:48:44.133+0000] {subprocess.py:93} INFO - 		::::::::::::::::::::::::::::::::::::::::::::::
[2025-10-09T01:48:44.134+0000] {subprocess.py:93} INFO - 
[2025-10-09T01:48:44.135+0000] {subprocess.py:93} INFO - 
[2025-10-09T01:48:44.136+0000] {subprocess.py:93} INFO - 
[2025-10-09T01:48:44.137+0000] {subprocess.py:93} INFO - :: USE VERBOSE OR DEBUG MESSAGE LEVEL FOR MORE DETAILS
[2025-10-09T01:48:44.137+0000] {subprocess.py:93} INFO - Exception in thread "main" java.lang.RuntimeException: [unresolved dependency: org.apache.spark#spark-sql-kafka-0-10_2.12;3.5.1: not found]
[2025-10-09T01:48:44.138+0000] {subprocess.py:93} INFO - 	at org.apache.spark.deploy.SparkSubmitUtils$.resolveMavenCoordinates(SparkSubmit.scala:1608)
[2025-10-09T01:48:44.139+0000] {subprocess.py:93} INFO - 	at org.apache.spark.util.DependencyUtils$.resolveMavenDependencies(DependencyUtils.scala:185)
[2025-10-09T01:48:44.140+0000] {subprocess.py:93} INFO - 	at org.apache.spark.deploy.SparkSubmit.prepareSubmitEnvironment(SparkSubmit.scala:334)
[2025-10-09T01:48:44.141+0000] {subprocess.py:93} INFO - 	at org.apache.spark.deploy.SparkSubmit.org$apache$spark$deploy$SparkSubmit$$runMain(SparkSubmit.scala:964)
[2025-10-09T01:48:44.142+0000] {subprocess.py:93} INFO - 	at org.apache.spark.deploy.SparkSubmit.doRunMain$1(SparkSubmit.scala:194)
[2025-10-09T01:48:44.142+0000] {subprocess.py:93} INFO - 	at org.apache.spark.deploy.SparkSubmit.submit(SparkSubmit.scala:217)
[2025-10-09T01:48:44.143+0000] {subprocess.py:93} INFO - 	at org.apache.spark.deploy.SparkSubmit.doSubmit(SparkSubmit.scala:91)
[2025-10-09T01:48:44.144+0000] {subprocess.py:93} INFO - 	at org.apache.spark.deploy.SparkSubmit$$anon$2.doSubmit(SparkSubmit.scala:1120)
[2025-10-09T01:48:44.145+0000] {subprocess.py:93} INFO - 	at org.apache.spark.deploy.SparkSubmit$.main(SparkSubmit.scala:1129)
[2025-10-09T01:48:44.146+0000] {subprocess.py:93} INFO - 	at org.apache.spark.deploy.SparkSubmit.main(SparkSubmit.scala)
[2025-10-09T01:48:44.147+0000] {subprocess.py:97} INFO - Command exited with return code 1
[2025-10-09T01:48:44.149+0000] {taskinstance.py:441} INFO - ::group::Post task execution logs
[2025-10-09T01:48:44.168+0000] {taskinstance.py:2905} ERROR - Task failed with exception
Traceback (most recent call last):
  File "/home/airflow/.local/lib/python3.12/site-packages/airflow/models/taskinstance.py", line 465, in _execute_task
    result = _execute_callable(context=context, **execute_callable_kwargs)
             ^^^^^^^^^^^^^^^^^^^^^^^^^^^^^^^^^^^^^^^^^^^^^^^^^^^^^^^^^^^^^
  File "/home/airflow/.local/lib/python3.12/site-packages/airflow/models/taskinstance.py", line 432, in _execute_callable
    return execute_callable(context=context, **execute_callable_kwargs)
           ^^^^^^^^^^^^^^^^^^^^^^^^^^^^^^^^^^^^^^^^^^^^^^^^^^^^^^^^^^^^
  File "/home/airflow/.local/lib/python3.12/site-packages/airflow/models/baseoperator.py", line 401, in wrapper
    return func(self, *args, **kwargs)
           ^^^^^^^^^^^^^^^^^^^^^^^^^^^
  File "/home/airflow/.local/lib/python3.12/site-packages/airflow/operators/bash.py", line 243, in execute
    raise AirflowException(
airflow.exceptions.AirflowException: Bash command failed. The command returned a non-zero exit code 1.
[2025-10-09T01:48:44.178+0000] {taskinstance.py:1206} INFO - Marking task as UP_FOR_RETRY. dag_id=restaurant_analytics, task_id=run_spark_stream, run_id=scheduled__2025-10-09T00:00:00+00:00, execution_date=20251009T000000, start_date=20251009T014823, end_date=20251009T014844
[2025-10-09T01:48:44.214+0000] {warnings.py:112} WARNING - /home/***/.local/lib/python3.12/site-packages/***/utils/email.py:154: RemovedInAirflow3Warning: Fetching SMTP credentials from configuration variables will be deprecated in a future release. Please set credentials using a connection instead.
  send_mime_email(e_from=mail_from, e_to=recipients, mime_msg=msg, conn_id=conn_id, dryrun=dryrun)

[2025-10-09T01:48:44.216+0000] {configuration.py:1053} WARNING - section/key [smtp/smtp_user] not found in config
[2025-10-09T01:48:44.217+0000] {email.py:271} INFO - Email alerting: attempt 1
[2025-10-09T01:48:44.237+0000] {configuration.py:1053} WARNING - section/key [smtp/smtp_user] not found in config
[2025-10-09T01:48:44.238+0000] {email.py:271} INFO - Email alerting: attempt 1
[2025-10-09T01:48:44.239+0000] {taskinstance.py:879} ERROR - Failed to send email to: ['quantruong1918@gmail.com']
Traceback (most recent call last):
  File "/home/airflow/.local/lib/python3.12/site-packages/airflow/models/taskinstance.py", line 2479, in _run_raw_task
    self._execute_task_with_callbacks(context, test_mode, session=session)
  File "/home/airflow/.local/lib/python3.12/site-packages/airflow/models/taskinstance.py", line 2676, in _execute_task_with_callbacks
    result = self._execute_task(context, task_orig)
             ^^^^^^^^^^^^^^^^^^^^^^^^^^^^^^^^^^^^^^
  File "/home/airflow/.local/lib/python3.12/site-packages/airflow/models/taskinstance.py", line 2701, in _execute_task
    return _execute_task(self, context, task_orig)
           ^^^^^^^^^^^^^^^^^^^^^^^^^^^^^^^^^^^^^^^
  File "/home/airflow/.local/lib/python3.12/site-packages/airflow/models/taskinstance.py", line 465, in _execute_task
    result = _execute_callable(context=context, **execute_callable_kwargs)
             ^^^^^^^^^^^^^^^^^^^^^^^^^^^^^^^^^^^^^^^^^^^^^^^^^^^^^^^^^^^^^
  File "/home/airflow/.local/lib/python3.12/site-packages/airflow/models/taskinstance.py", line 432, in _execute_callable
    return execute_callable(context=context, **execute_callable_kwargs)
           ^^^^^^^^^^^^^^^^^^^^^^^^^^^^^^^^^^^^^^^^^^^^^^^^^^^^^^^^^^^^
  File "/home/airflow/.local/lib/python3.12/site-packages/airflow/models/baseoperator.py", line 401, in wrapper
    return func(self, *args, **kwargs)
           ^^^^^^^^^^^^^^^^^^^^^^^^^^^
  File "/home/airflow/.local/lib/python3.12/site-packages/airflow/operators/bash.py", line 243, in execute
    raise AirflowException(
airflow.exceptions.AirflowException: Bash command failed. The command returned a non-zero exit code 1.

During handling of the above exception, another exception occurred:

Traceback (most recent call last):
  File "/home/airflow/.local/lib/python3.12/site-packages/airflow/models/taskinstance.py", line 1063, in _email_alert
    send_email(task.email, subject, html_content)
  File "/home/airflow/.local/lib/python3.12/site-packages/airflow/utils/email.py", line 80, in send_email
    return backend(
           ^^^^^^^^
  File "/home/airflow/.local/lib/python3.12/site-packages/airflow/utils/email.py", line 154, in send_email_smtp
    send_mime_email(e_from=mail_from, e_to=recipients, mime_msg=msg, conn_id=conn_id, dryrun=dryrun)
  File "/home/airflow/.local/lib/python3.12/site-packages/airflow/utils/email.py", line 273, in send_mime_email
    smtp_conn = _get_smtp_connection(smtp_host, smtp_port, smtp_timeout, smtp_ssl)
                ^^^^^^^^^^^^^^^^^^^^^^^^^^^^^^^^^^^^^^^^^^^^^^^^^^^^^^^^^^^^^^^^^^
  File "/home/airflow/.local/lib/python3.12/site-packages/airflow/utils/email.py", line 317, in _get_smtp_connection
    return smtplib.SMTP(host=host, port=port, timeout=timeout)
           ^^^^^^^^^^^^^^^^^^^^^^^^^^^^^^^^^^^^^^^^^^^^^^^^^^^
  File "/usr/local/lib/python3.12/smtplib.py", line 255, in __init__
    (code, msg) = self.connect(host, port)
                  ^^^^^^^^^^^^^^^^^^^^^^^^
  File "/usr/local/lib/python3.12/smtplib.py", line 341, in connect
    self.sock = self._get_socket(host, port, self.timeout)
                ^^^^^^^^^^^^^^^^^^^^^^^^^^^^^^^^^^^^^^^^^^
  File "/usr/local/lib/python3.12/smtplib.py", line 312, in _get_socket
    return socket.create_connection((host, port), timeout,
           ^^^^^^^^^^^^^^^^^^^^^^^^^^^^^^^^^^^^^^^^^^^^^^^
  File "/usr/local/lib/python3.12/socket.py", line 853, in create_connection
    raise exceptions[0]
  File "/usr/local/lib/python3.12/socket.py", line 838, in create_connection
    sock.connect(sa)
ConnectionRefusedError: [Errno 111] Connection refused

During handling of the above exception, another exception occurred:

Traceback (most recent call last):
  File "/home/airflow/.local/lib/python3.12/site-packages/airflow/models/taskinstance.py", line 877, in _handle_failure
    task_instance.email_alert(error, failure_context["task"])
  File "/home/airflow/.local/lib/python3.12/site-packages/airflow/models/taskinstance.py", line 3163, in email_alert
    _email_alert(task_instance=self, exception=exception, task=task)
  File "/home/airflow/.local/lib/python3.12/site-packages/airflow/models/taskinstance.py", line 1065, in _email_alert
    send_email(task.email, subject, html_content_err)
  File "/home/airflow/.local/lib/python3.12/site-packages/airflow/utils/email.py", line 80, in send_email
    return backend(
           ^^^^^^^^
  File "/home/airflow/.local/lib/python3.12/site-packages/airflow/utils/email.py", line 154, in send_email_smtp
    send_mime_email(e_from=mail_from, e_to=recipients, mime_msg=msg, conn_id=conn_id, dryrun=dryrun)
  File "/home/airflow/.local/lib/python3.12/site-packages/airflow/utils/email.py", line 273, in send_mime_email
    smtp_conn = _get_smtp_connection(smtp_host, smtp_port, smtp_timeout, smtp_ssl)
                ^^^^^^^^^^^^^^^^^^^^^^^^^^^^^^^^^^^^^^^^^^^^^^^^^^^^^^^^^^^^^^^^^^
  File "/home/airflow/.local/lib/python3.12/site-packages/airflow/utils/email.py", line 317, in _get_smtp_connection
    return smtplib.SMTP(host=host, port=port, timeout=timeout)
           ^^^^^^^^^^^^^^^^^^^^^^^^^^^^^^^^^^^^^^^^^^^^^^^^^^^
  File "/usr/local/lib/python3.12/smtplib.py", line 255, in __init__
    (code, msg) = self.connect(host, port)
                  ^^^^^^^^^^^^^^^^^^^^^^^^
  File "/usr/local/lib/python3.12/smtplib.py", line 341, in connect
    self.sock = self._get_socket(host, port, self.timeout)
                ^^^^^^^^^^^^^^^^^^^^^^^^^^^^^^^^^^^^^^^^^^
  File "/usr/local/lib/python3.12/smtplib.py", line 312, in _get_socket
    return socket.create_connection((host, port), timeout,
           ^^^^^^^^^^^^^^^^^^^^^^^^^^^^^^^^^^^^^^^^^^^^^^^
  File "/usr/local/lib/python3.12/socket.py", line 853, in create_connection
    raise exceptions[0]
  File "/usr/local/lib/python3.12/socket.py", line 838, in create_connection
    sock.connect(sa)
ConnectionRefusedError: [Errno 111] Connection refused
[2025-10-09T01:48:44.279+0000] {standard_task_runner.py:110} ERROR - Failed to execute job 231 for task run_spark_stream (Bash command failed. The command returned a non-zero exit code 1.; 101)
[2025-10-09T01:48:44.331+0000] {local_task_job_runner.py:243} INFO - Task exited with return code 1
[2025-10-09T01:48:44.391+0000] {taskinstance.py:3503} INFO - 0 downstream tasks scheduled from follow-on schedule check
[2025-10-09T01:48:44.394+0000] {local_task_job_runner.py:222} INFO - ::endgroup::
