[2025-10-10T02:55:15.429+0000] {local_task_job_runner.py:120} INFO - ::group::Pre task execution logs
[2025-10-10T02:55:15.484+0000] {taskinstance.py:2076} INFO - Dependencies all met for dep_context=non-requeueable deps ti=<TaskInstance: restaurant_analytics.check_spark_streaming scheduled__2025-10-09T15:00:00+00:00 [queued]>
[2025-10-10T02:55:15.500+0000] {taskinstance.py:2076} INFO - Dependencies all met for dep_context=requeueable deps ti=<TaskInstance: restaurant_analytics.check_spark_streaming scheduled__2025-10-09T15:00:00+00:00 [queued]>
[2025-10-10T02:55:15.511+0000] {taskinstance.py:2306} INFO - Starting attempt 2 of 2
[2025-10-10T02:55:15.540+0000] {taskinstance.py:2330} INFO - Executing <Task(PythonOperator): check_spark_streaming> on 2025-10-09 15:00:00+00:00
[2025-10-10T02:55:15.559+0000] {warnings.py:112} WARNING - /home/***/.local/lib/python3.12/site-packages/***/task/task_runner/standard_task_runner.py:62: DeprecationWarning: This process (pid=140) is multi-threaded, use of fork() may lead to deadlocks in the child.
  pid = os.fork()

[2025-10-10T02:55:15.565+0000] {standard_task_runner.py:64} INFO - Started process 144 to run task
[2025-10-10T02:55:15.563+0000] {standard_task_runner.py:90} INFO - Running: ['***', 'tasks', 'run', 'restaurant_analytics', 'check_spark_streaming', 'scheduled__2025-10-09T15:00:00+00:00', '--job-id', '309', '--raw', '--subdir', 'DAGS_FOLDER/restaurant_dag.py', '--cfg-path', '/tmp/tmpjsf6puux']
[2025-10-10T02:55:15.570+0000] {standard_task_runner.py:91} INFO - Job 309: Subtask check_spark_streaming
[2025-10-10T02:55:15.738+0000] {task_command.py:426} INFO - Running <TaskInstance: restaurant_analytics.check_spark_streaming scheduled__2025-10-09T15:00:00+00:00 [running]> on host dd5baa7fba45
[2025-10-10T02:55:15.911+0000] {taskinstance.py:2648} INFO - Exporting env vars: AIRFLOW_CTX_DAG_EMAIL='quantruong1918@gmail.com' AIRFLOW_CTX_DAG_OWNER='***' AIRFLOW_CTX_DAG_ID='restaurant_analytics' AIRFLOW_CTX_TASK_ID='check_spark_streaming' AIRFLOW_CTX_EXECUTION_DATE='2025-10-09T15:00:00+00:00' AIRFLOW_CTX_TRY_NUMBER='2' AIRFLOW_CTX_DAG_RUN_ID='scheduled__2025-10-09T15:00:00+00:00'
[2025-10-10T02:55:15.915+0000] {taskinstance.py:430} INFO - ::endgroup::
[2025-10-10T02:55:17.241+0000] {taskinstance.py:441} INFO - ::group::Post task execution logs
[2025-10-10T02:55:17.242+0000] {taskinstance.py:2905} ERROR - Task failed with exception
Traceback (most recent call last):
  File "/home/airflow/.local/lib/python3.12/site-packages/urllib3/connection.py", line 203, in _new_conn
    sock = connection.create_connection(
           ^^^^^^^^^^^^^^^^^^^^^^^^^^^^^
  File "/home/airflow/.local/lib/python3.12/site-packages/urllib3/util/connection.py", line 60, in create_connection
    for res in socket.getaddrinfo(host, port, family, socket.SOCK_STREAM):
               ^^^^^^^^^^^^^^^^^^^^^^^^^^^^^^^^^^^^^^^^^^^^^^^^^^^^^^^^^^
  File "/usr/local/lib/python3.12/socket.py", line 964, in getaddrinfo
    for res in _socket.getaddrinfo(host, port, family, type, proto, flags):
               ^^^^^^^^^^^^^^^^^^^^^^^^^^^^^^^^^^^^^^^^^^^^^^^^^^^^^^^^^^^
socket.gaierror: [Errno -5] No address associated with hostname

The above exception was the direct cause of the following exception:

Traceback (most recent call last):
  File "/home/airflow/.local/lib/python3.12/site-packages/urllib3/connectionpool.py", line 791, in urlopen
    response = self._make_request(
               ^^^^^^^^^^^^^^^^^^^
  File "/home/airflow/.local/lib/python3.12/site-packages/urllib3/connectionpool.py", line 497, in _make_request
    conn.request(
  File "/home/airflow/.local/lib/python3.12/site-packages/urllib3/connection.py", line 395, in request
    self.endheaders()
  File "/usr/local/lib/python3.12/http/client.py", line 1331, in endheaders
    self._send_output(message_body, encode_chunked=encode_chunked)
  File "/usr/local/lib/python3.12/http/client.py", line 1091, in _send_output
    self.send(msg)
  File "/usr/local/lib/python3.12/http/client.py", line 1035, in send
    self.connect()
  File "/home/airflow/.local/lib/python3.12/site-packages/urllib3/connection.py", line 243, in connect
    self.sock = self._new_conn()
                ^^^^^^^^^^^^^^^^
  File "/home/airflow/.local/lib/python3.12/site-packages/urllib3/connection.py", line 210, in _new_conn
    raise NameResolutionError(self.host, self, e) from e
urllib3.exceptions.NameResolutionError: <urllib3.connection.HTTPConnection object at 0x7415396ec680>: Failed to resolve 'spark-streaming' ([Errno -5] No address associated with hostname)

The above exception was the direct cause of the following exception:

Traceback (most recent call last):
  File "/home/airflow/.local/lib/python3.12/site-packages/requests/adapters.py", line 667, in send
    resp = conn.urlopen(
           ^^^^^^^^^^^^^
  File "/home/airflow/.local/lib/python3.12/site-packages/urllib3/connectionpool.py", line 845, in urlopen
    retries = retries.increment(
              ^^^^^^^^^^^^^^^^^^
  File "/home/airflow/.local/lib/python3.12/site-packages/urllib3/util/retry.py", line 515, in increment
    raise MaxRetryError(_pool, url, reason) from reason  # type: ignore[arg-type]
    ^^^^^^^^^^^^^^^^^^^^^^^^^^^^^^^^^^^^^^^^^^^^^^^^^^^
urllib3.exceptions.MaxRetryError: HTTPConnectionPool(host='spark-streaming', port=4040): Max retries exceeded with url: / (Caused by NameResolutionError("<urllib3.connection.HTTPConnection object at 0x7415396ec680>: Failed to resolve 'spark-streaming' ([Errno -5] No address associated with hostname)"))

During handling of the above exception, another exception occurred:

Traceback (most recent call last):
  File "/opt/airflow/dags/restaurant_dag.py", line 34, in check_streaming_status
    resp = requests.get("http://spark-streaming:4040", timeout=5)
           ^^^^^^^^^^^^^^^^^^^^^^^^^^^^^^^^^^^^^^^^^^^^^^^^^^^^^^
  File "/home/airflow/.local/lib/python3.12/site-packages/requests/api.py", line 73, in get
    return request("get", url, params=params, **kwargs)
           ^^^^^^^^^^^^^^^^^^^^^^^^^^^^^^^^^^^^^^^^^^^^
  File "/home/airflow/.local/lib/python3.12/site-packages/requests/api.py", line 59, in request
    return session.request(method=method, url=url, **kwargs)
           ^^^^^^^^^^^^^^^^^^^^^^^^^^^^^^^^^^^^^^^^^^^^^^^^^
  File "/home/airflow/.local/lib/python3.12/site-packages/requests/sessions.py", line 589, in request
    resp = self.send(prep, **send_kwargs)
           ^^^^^^^^^^^^^^^^^^^^^^^^^^^^^^
  File "/home/airflow/.local/lib/python3.12/site-packages/requests/sessions.py", line 703, in send
    r = adapter.send(request, **kwargs)
        ^^^^^^^^^^^^^^^^^^^^^^^^^^^^^^^
  File "/home/airflow/.local/lib/python3.12/site-packages/requests/adapters.py", line 700, in send
    raise ConnectionError(e, request=request)
requests.exceptions.ConnectionError: HTTPConnectionPool(host='spark-streaming', port=4040): Max retries exceeded with url: / (Caused by NameResolutionError("<urllib3.connection.HTTPConnection object at 0x7415396ec680>: Failed to resolve 'spark-streaming' ([Errno -5] No address associated with hostname)"))

During handling of the above exception, another exception occurred:

Traceback (most recent call last):
  File "/home/airflow/.local/lib/python3.12/site-packages/airflow/models/taskinstance.py", line 465, in _execute_task
    result = _execute_callable(context=context, **execute_callable_kwargs)
             ^^^^^^^^^^^^^^^^^^^^^^^^^^^^^^^^^^^^^^^^^^^^^^^^^^^^^^^^^^^^^
  File "/home/airflow/.local/lib/python3.12/site-packages/airflow/models/taskinstance.py", line 432, in _execute_callable
    return execute_callable(context=context, **execute_callable_kwargs)
           ^^^^^^^^^^^^^^^^^^^^^^^^^^^^^^^^^^^^^^^^^^^^^^^^^^^^^^^^^^^^
  File "/home/airflow/.local/lib/python3.12/site-packages/airflow/models/baseoperator.py", line 401, in wrapper
    return func(self, *args, **kwargs)
           ^^^^^^^^^^^^^^^^^^^^^^^^^^^
  File "/home/airflow/.local/lib/python3.12/site-packages/airflow/operators/python.py", line 235, in execute
    return_value = self.execute_callable()
                   ^^^^^^^^^^^^^^^^^^^^^^^
  File "/home/airflow/.local/lib/python3.12/site-packages/airflow/operators/python.py", line 252, in execute_callable
    return self.python_callable(*self.op_args, **self.op_kwargs)
           ^^^^^^^^^^^^^^^^^^^^^^^^^^^^^^^^^^^^^^^^^^^^^^^^^^^^^
  File "/opt/airflow/dags/restaurant_dag.py", line 40, in check_streaming_status
    raise Exception(f"❌ Spark streaming service is NOT running or unreachable: {e}")
Exception: ❌ Spark streaming service is NOT running or unreachable: HTTPConnectionPool(host='spark-streaming', port=4040): Max retries exceeded with url: / (Caused by NameResolutionError("<urllib3.connection.HTTPConnection object at 0x7415396ec680>: Failed to resolve 'spark-streaming' ([Errno -5] No address associated with hostname)"))
[2025-10-10T02:55:17.271+0000] {taskinstance.py:1206} INFO - Marking task as FAILED. dag_id=restaurant_analytics, task_id=check_spark_streaming, run_id=scheduled__2025-10-09T15:00:00+00:00, execution_date=20251009T150000, start_date=20251010T025515, end_date=20251010T025517
[2025-10-10T02:55:17.302+0000] {standard_task_runner.py:110} ERROR - Failed to execute job 309 for task check_spark_streaming (❌ Spark streaming service is NOT running or unreachable: HTTPConnectionPool(host='spark-streaming', port=4040): Max retries exceeded with url: / (Caused by NameResolutionError("<urllib3.connection.HTTPConnection object at 0x7415396ec680>: Failed to resolve 'spark-streaming' ([Errno -5] No address associated with hostname)")); 144)
[2025-10-10T02:55:17.358+0000] {local_task_job_runner.py:243} INFO - Task exited with return code 1
[2025-10-10T02:55:17.390+0000] {taskinstance.py:3503} INFO - 0 downstream tasks scheduled from follow-on schedule check
[2025-10-10T02:55:17.396+0000] {local_task_job_runner.py:222} INFO - ::endgroup::
