[2025-10-10T04:00:10.072+0000] {local_task_job_runner.py:120} INFO - ::group::Pre task execution logs
[2025-10-10T04:00:10.143+0000] {taskinstance.py:2076} INFO - Dependencies all met for dep_context=non-requeueable deps ti=<TaskInstance: restaurant_analytics.retrain_model scheduled__2025-10-10T03:00:00+00:00 [queued]>
[2025-10-10T04:00:10.161+0000] {taskinstance.py:2076} INFO - Dependencies all met for dep_context=requeueable deps ti=<TaskInstance: restaurant_analytics.retrain_model scheduled__2025-10-10T03:00:00+00:00 [queued]>
[2025-10-10T04:00:10.165+0000] {taskinstance.py:2306} INFO - Starting attempt 1 of 2
[2025-10-10T04:00:10.195+0000] {taskinstance.py:2330} INFO - Executing <Task(BashOperator): retrain_model> on 2025-10-10 03:00:00+00:00
[2025-10-10T04:00:10.211+0000] {warnings.py:112} WARNING - /home/***/.local/lib/python3.12/site-packages/***/task/task_runner/standard_task_runner.py:62: DeprecationWarning: This process (pid=929) is multi-threaded, use of fork() may lead to deadlocks in the child.
  pid = os.fork()

[2025-10-10T04:00:10.215+0000] {standard_task_runner.py:64} INFO - Started process 931 to run task
[2025-10-10T04:00:10.214+0000] {standard_task_runner.py:90} INFO - Running: ['***', 'tasks', 'run', 'restaurant_analytics', 'retrain_model', 'scheduled__2025-10-10T03:00:00+00:00', '--job-id', '314', '--raw', '--subdir', 'DAGS_FOLDER/restaurant_dag.py', '--cfg-path', '/tmp/tmp3butlg6i']
[2025-10-10T04:00:10.220+0000] {standard_task_runner.py:91} INFO - Job 314: Subtask retrain_model
[2025-10-10T04:00:10.346+0000] {task_command.py:426} INFO - Running <TaskInstance: restaurant_analytics.retrain_model scheduled__2025-10-10T03:00:00+00:00 [running]> on host dd5baa7fba45
[2025-10-10T04:00:10.552+0000] {taskinstance.py:2648} INFO - Exporting env vars: AIRFLOW_CTX_DAG_EMAIL='quantruong1918@gmail.com' AIRFLOW_CTX_DAG_OWNER='***' AIRFLOW_CTX_DAG_ID='restaurant_analytics' AIRFLOW_CTX_TASK_ID='retrain_model' AIRFLOW_CTX_EXECUTION_DATE='2025-10-10T03:00:00+00:00' AIRFLOW_CTX_TRY_NUMBER='1' AIRFLOW_CTX_DAG_RUN_ID='scheduled__2025-10-10T03:00:00+00:00'
[2025-10-10T04:00:10.556+0000] {taskinstance.py:430} INFO - ::endgroup::
[2025-10-10T04:00:10.558+0000] {subprocess.py:63} INFO - Tmp dir root location: /tmp
[2025-10-10T04:00:10.561+0000] {subprocess.py:75} INFO - Running command: ['/usr/bin/bash', '-c', 'export PYSPARK_PYTHON=/usr/local/bin/python && export PYSPARK_DRIVER_PYTHON=/usr/local/bin/python && /opt/spark/bin/spark-submit --master local[*] /opt/***/dags/train_lr.py']
[2025-10-10T04:00:10.587+0000] {subprocess.py:86} INFO - Output:
[2025-10-10T04:00:22.666+0000] {subprocess.py:93} INFO - 25/10/10 04:00:22 INFO SparkContext: Running Spark version 3.5.1
[2025-10-10T04:00:22.669+0000] {subprocess.py:93} INFO - 25/10/10 04:00:22 INFO SparkContext: OS info Linux, 6.6.87.1-microsoft-standard-WSL2, amd64
[2025-10-10T04:00:22.670+0000] {subprocess.py:93} INFO - 25/10/10 04:00:22 INFO SparkContext: Java version 17.0.16
[2025-10-10T04:00:22.787+0000] {subprocess.py:93} INFO - 25/10/10 04:00:22 WARN NativeCodeLoader: Unable to load native-hadoop library for your platform... using builtin-java classes where applicable
[2025-10-10T04:00:22.958+0000] {subprocess.py:93} INFO - 25/10/10 04:00:22 INFO ResourceUtils: ==============================================================
[2025-10-10T04:00:22.959+0000] {subprocess.py:93} INFO - 25/10/10 04:00:22 INFO ResourceUtils: No custom resources configured for spark.driver.
[2025-10-10T04:00:22.960+0000] {subprocess.py:93} INFO - 25/10/10 04:00:22 INFO ResourceUtils: ==============================================================
[2025-10-10T04:00:22.961+0000] {subprocess.py:93} INFO - 25/10/10 04:00:22 INFO SparkContext: Submitted application: TrainLR
[2025-10-10T04:00:22.991+0000] {subprocess.py:93} INFO - 25/10/10 04:00:22 INFO ResourceProfile: Default ResourceProfile created, executor resources: Map(cores -> name: cores, amount: 1, script: , vendor: , memory -> name: memory, amount: 1024, script: , vendor: , offHeap -> name: offHeap, amount: 0, script: , vendor: ), task resources: Map(cpus -> name: cpus, amount: 1.0)
[2025-10-10T04:00:23.002+0000] {subprocess.py:93} INFO - 25/10/10 04:00:23 INFO ResourceProfile: Limiting resource is cpu
[2025-10-10T04:00:23.003+0000] {subprocess.py:93} INFO - 25/10/10 04:00:23 INFO ResourceProfileManager: Added ResourceProfile id: 0
[2025-10-10T04:00:23.100+0000] {subprocess.py:93} INFO - 25/10/10 04:00:23 INFO SecurityManager: Changing view acls to: ***
[2025-10-10T04:00:23.101+0000] {subprocess.py:93} INFO - 25/10/10 04:00:23 INFO SecurityManager: Changing modify acls to: ***
[2025-10-10T04:00:23.102+0000] {subprocess.py:93} INFO - 25/10/10 04:00:23 INFO SecurityManager: Changing view acls groups to:
[2025-10-10T04:00:23.103+0000] {subprocess.py:93} INFO - 25/10/10 04:00:23 INFO SecurityManager: Changing modify acls groups to:
[2025-10-10T04:00:23.104+0000] {subprocess.py:93} INFO - 25/10/10 04:00:23 INFO SecurityManager: SecurityManager: authentication disabled; ui acls disabled; users with view permissions: ***; groups with view permissions: EMPTY; users with modify permissions: ***; groups with modify permissions: EMPTY
[2025-10-10T04:00:23.572+0000] {subprocess.py:93} INFO - 25/10/10 04:00:23 INFO Utils: Successfully started service 'sparkDriver' on port 32939.
[2025-10-10T04:00:23.632+0000] {subprocess.py:93} INFO - 25/10/10 04:00:23 INFO SparkEnv: Registering MapOutputTracker
[2025-10-10T04:00:23.700+0000] {subprocess.py:93} INFO - 25/10/10 04:00:23 INFO SparkEnv: Registering BlockManagerMaster
[2025-10-10T04:00:23.743+0000] {subprocess.py:93} INFO - 25/10/10 04:00:23 INFO BlockManagerMasterEndpoint: Using org.apache.spark.storage.DefaultTopologyMapper for getting topology information
[2025-10-10T04:00:23.745+0000] {subprocess.py:93} INFO - 25/10/10 04:00:23 INFO BlockManagerMasterEndpoint: BlockManagerMasterEndpoint up
[2025-10-10T04:00:23.754+0000] {subprocess.py:93} INFO - 25/10/10 04:00:23 INFO SparkEnv: Registering BlockManagerMasterHeartbeat
[2025-10-10T04:00:23.807+0000] {subprocess.py:93} INFO - 25/10/10 04:00:23 INFO DiskBlockManager: Created local directory at /tmp/blockmgr-ca59821f-21b2-471a-838d-54ae01dda24a
[2025-10-10T04:00:23.836+0000] {subprocess.py:93} INFO - 25/10/10 04:00:23 INFO MemoryStore: MemoryStore started with capacity 434.4 MiB
[2025-10-10T04:00:23.863+0000] {subprocess.py:93} INFO - 25/10/10 04:00:23 INFO SparkEnv: Registering OutputCommitCoordinator
[2025-10-10T04:00:24.125+0000] {subprocess.py:93} INFO - 25/10/10 04:00:24 INFO JettyUtils: Start Jetty 0.0.0.0:4040 for SparkUI
[2025-10-10T04:00:24.244+0000] {subprocess.py:93} INFO - 25/10/10 04:00:24 INFO Utils: Successfully started service 'SparkUI' on port 4040.
[2025-10-10T04:00:24.528+0000] {subprocess.py:93} INFO - 25/10/10 04:00:24 INFO Executor: Starting executor ID driver on host dd5baa7fba45
[2025-10-10T04:00:24.530+0000] {subprocess.py:93} INFO - 25/10/10 04:00:24 INFO Executor: OS info Linux, 6.6.87.1-microsoft-standard-WSL2, amd64
[2025-10-10T04:00:24.532+0000] {subprocess.py:93} INFO - 25/10/10 04:00:24 INFO Executor: Java version 17.0.16
[2025-10-10T04:00:24.555+0000] {subprocess.py:93} INFO - 25/10/10 04:00:24 INFO Executor: Starting executor with user classpath (userClassPathFirst = false): ''
[2025-10-10T04:00:24.558+0000] {subprocess.py:93} INFO - 25/10/10 04:00:24 INFO Executor: Created or updated repl class loader org.apache.spark.util.MutableURLClassLoader@282a31fd for default.
[2025-10-10T04:00:24.627+0000] {subprocess.py:93} INFO - 25/10/10 04:00:24 INFO Utils: Successfully started service 'org.apache.spark.network.netty.NettyBlockTransferService' on port 37123.
[2025-10-10T04:00:24.634+0000] {subprocess.py:93} INFO - 25/10/10 04:00:24 INFO NettyBlockTransferService: Server created on dd5baa7fba45:37123
[2025-10-10T04:00:24.635+0000] {subprocess.py:93} INFO - 25/10/10 04:00:24 INFO BlockManager: Using org.apache.spark.storage.RandomBlockReplicationPolicy for block replication policy
[2025-10-10T04:00:24.655+0000] {subprocess.py:93} INFO - 25/10/10 04:00:24 INFO BlockManagerMaster: Registering BlockManager BlockManagerId(driver, dd5baa7fba45, 37123, None)
[2025-10-10T04:00:24.668+0000] {subprocess.py:93} INFO - 25/10/10 04:00:24 INFO BlockManagerMasterEndpoint: Registering block manager dd5baa7fba45:37123 with 434.4 MiB RAM, BlockManagerId(driver, dd5baa7fba45, 37123, None)
[2025-10-10T04:00:24.674+0000] {subprocess.py:93} INFO - 25/10/10 04:00:24 INFO BlockManagerMaster: Registered BlockManager BlockManagerId(driver, dd5baa7fba45, 37123, None)
[2025-10-10T04:00:24.680+0000] {subprocess.py:93} INFO - 25/10/10 04:00:24 INFO BlockManager: Initialized BlockManager: BlockManagerId(driver, dd5baa7fba45, 37123, None)
[2025-10-10T04:00:26.197+0000] {subprocess.py:93} INFO - 25/10/10 04:00:26 INFO SharedState: Setting hive.metastore.warehouse.dir ('null') to the value of spark.sql.warehouse.dir.
[2025-10-10T04:00:26.222+0000] {subprocess.py:93} INFO - 25/10/10 04:00:26 INFO SharedState: Warehouse path is 'file:/tmp/***tmp6ssgnlmw/spark-warehouse'.
[2025-10-10T04:00:29.491+0000] {subprocess.py:93} INFO - Traceback (most recent call last):
[2025-10-10T04:00:29.493+0000] {subprocess.py:93} INFO -   File "/opt/***/dags/train_lr.py", line 7, in <module>
[2025-10-10T04:00:29.499+0000] {subprocess.py:93} INFO -     df = spark.read.csv('historical_orders.csv', header=True, inferSchema=True)
[2025-10-10T04:00:29.500+0000] {subprocess.py:93} INFO -          ^^^^^^^^^^^^^^^^^^^^^^^^^^^^^^^^^^^^^^^^^^^^^^^^^^^^^^^^^^^^^^^^^^^^^^
[2025-10-10T04:00:29.502+0000] {subprocess.py:93} INFO -   File "/opt/spark/python/lib/pyspark.zip/pyspark/sql/readwriter.py", line 740, in csv
[2025-10-10T04:00:29.503+0000] {subprocess.py:93} INFO -   File "/opt/spark/python/lib/py4j-0.10.9.7-src.zip/py4j/java_gateway.py", line 1322, in __call__
[2025-10-10T04:00:29.504+0000] {subprocess.py:93} INFO -   File "/opt/spark/python/lib/pyspark.zip/pyspark/errors/exceptions/captured.py", line 185, in deco
[2025-10-10T04:00:29.528+0000] {subprocess.py:93} INFO - pyspark.errors.exceptions.captured.AnalysisException: [PATH_NOT_FOUND] Path does not exist: file:/tmp/***tmp6ssgnlmw/historical_orders.csv.
[2025-10-10T04:00:29.770+0000] {subprocess.py:93} INFO - 25/10/10 04:00:29 INFO SparkContext: Invoking stop() from shutdown hook
[2025-10-10T04:00:29.772+0000] {subprocess.py:93} INFO - 25/10/10 04:00:29 INFO SparkContext: SparkContext is stopping with exitCode 0.
[2025-10-10T04:00:29.797+0000] {subprocess.py:93} INFO - 25/10/10 04:00:29 INFO SparkUI: Stopped Spark web UI at http://dd5baa7fba45:4040
[2025-10-10T04:00:29.820+0000] {subprocess.py:93} INFO - 25/10/10 04:00:29 INFO MapOutputTrackerMasterEndpoint: MapOutputTrackerMasterEndpoint stopped!
[2025-10-10T04:00:29.855+0000] {subprocess.py:93} INFO - 25/10/10 04:00:29 INFO MemoryStore: MemoryStore cleared
[2025-10-10T04:00:29.856+0000] {subprocess.py:93} INFO - 25/10/10 04:00:29 INFO BlockManager: BlockManager stopped
[2025-10-10T04:00:29.872+0000] {subprocess.py:93} INFO - 25/10/10 04:00:29 INFO BlockManagerMaster: BlockManagerMaster stopped
[2025-10-10T04:00:29.881+0000] {subprocess.py:93} INFO - 25/10/10 04:00:29 INFO OutputCommitCoordinator$OutputCommitCoordinatorEndpoint: OutputCommitCoordinator stopped!
[2025-10-10T04:00:29.915+0000] {subprocess.py:93} INFO - 25/10/10 04:00:29 INFO SparkContext: Successfully stopped SparkContext
[2025-10-10T04:00:29.920+0000] {subprocess.py:93} INFO - 25/10/10 04:00:29 INFO ShutdownHookManager: Shutdown hook called
[2025-10-10T04:00:29.921+0000] {subprocess.py:93} INFO - 25/10/10 04:00:29 INFO ShutdownHookManager: Deleting directory /tmp/spark-b492e8de-a8f4-41fc-98f6-5a5b6ec11aa3
[2025-10-10T04:00:29.932+0000] {subprocess.py:93} INFO - 25/10/10 04:00:29 INFO ShutdownHookManager: Deleting directory /tmp/spark-db764b43-694c-4ddf-855a-a97b3acc5fd2/pyspark-f793175a-b7a1-4b01-98d5-5fcccfdb1985
[2025-10-10T04:00:29.940+0000] {subprocess.py:93} INFO - 25/10/10 04:00:29 INFO ShutdownHookManager: Deleting directory /tmp/spark-db764b43-694c-4ddf-855a-a97b3acc5fd2
[2025-10-10T04:00:30.050+0000] {subprocess.py:97} INFO - Command exited with return code 1
[2025-10-10T04:00:30.052+0000] {taskinstance.py:441} INFO - ::group::Post task execution logs
[2025-10-10T04:00:30.072+0000] {taskinstance.py:2905} ERROR - Task failed with exception
Traceback (most recent call last):
  File "/home/airflow/.local/lib/python3.12/site-packages/airflow/models/taskinstance.py", line 465, in _execute_task
    result = _execute_callable(context=context, **execute_callable_kwargs)
             ^^^^^^^^^^^^^^^^^^^^^^^^^^^^^^^^^^^^^^^^^^^^^^^^^^^^^^^^^^^^^
  File "/home/airflow/.local/lib/python3.12/site-packages/airflow/models/taskinstance.py", line 432, in _execute_callable
    return execute_callable(context=context, **execute_callable_kwargs)
           ^^^^^^^^^^^^^^^^^^^^^^^^^^^^^^^^^^^^^^^^^^^^^^^^^^^^^^^^^^^^
  File "/home/airflow/.local/lib/python3.12/site-packages/airflow/models/baseoperator.py", line 401, in wrapper
    return func(self, *args, **kwargs)
           ^^^^^^^^^^^^^^^^^^^^^^^^^^^
  File "/home/airflow/.local/lib/python3.12/site-packages/airflow/operators/bash.py", line 243, in execute
    raise AirflowException(
airflow.exceptions.AirflowException: Bash command failed. The command returned a non-zero exit code 1.
[2025-10-10T04:00:30.086+0000] {taskinstance.py:1206} INFO - Marking task as UP_FOR_RETRY. dag_id=restaurant_analytics, task_id=retrain_model, run_id=scheduled__2025-10-10T03:00:00+00:00, execution_date=20251010T030000, start_date=20251010T040010, end_date=20251010T040030
[2025-10-10T04:00:30.122+0000] {warnings.py:112} WARNING - /home/***/.local/lib/python3.12/site-packages/***/utils/email.py:154: RemovedInAirflow3Warning: Fetching SMTP credentials from configuration variables will be deprecated in a future release. Please set credentials using a connection instead.
  send_mime_email(e_from=mail_from, e_to=recipients, mime_msg=msg, conn_id=conn_id, dryrun=dryrun)

[2025-10-10T04:00:30.124+0000] {configuration.py:1053} WARNING - section/key [smtp/smtp_user] not found in config
[2025-10-10T04:00:30.126+0000] {email.py:271} INFO - Email alerting: attempt 1
[2025-10-10T04:00:30.140+0000] {configuration.py:1053} WARNING - section/key [smtp/smtp_user] not found in config
[2025-10-10T04:00:30.141+0000] {email.py:271} INFO - Email alerting: attempt 1
[2025-10-10T04:00:30.144+0000] {taskinstance.py:879} ERROR - Failed to send email to: ['quantruong1918@gmail.com']
Traceback (most recent call last):
  File "/home/airflow/.local/lib/python3.12/site-packages/airflow/models/taskinstance.py", line 2479, in _run_raw_task
    self._execute_task_with_callbacks(context, test_mode, session=session)
  File "/home/airflow/.local/lib/python3.12/site-packages/airflow/models/taskinstance.py", line 2676, in _execute_task_with_callbacks
    result = self._execute_task(context, task_orig)
             ^^^^^^^^^^^^^^^^^^^^^^^^^^^^^^^^^^^^^^
  File "/home/airflow/.local/lib/python3.12/site-packages/airflow/models/taskinstance.py", line 2701, in _execute_task
    return _execute_task(self, context, task_orig)
           ^^^^^^^^^^^^^^^^^^^^^^^^^^^^^^^^^^^^^^^
  File "/home/airflow/.local/lib/python3.12/site-packages/airflow/models/taskinstance.py", line 465, in _execute_task
    result = _execute_callable(context=context, **execute_callable_kwargs)
             ^^^^^^^^^^^^^^^^^^^^^^^^^^^^^^^^^^^^^^^^^^^^^^^^^^^^^^^^^^^^^
  File "/home/airflow/.local/lib/python3.12/site-packages/airflow/models/taskinstance.py", line 432, in _execute_callable
    return execute_callable(context=context, **execute_callable_kwargs)
           ^^^^^^^^^^^^^^^^^^^^^^^^^^^^^^^^^^^^^^^^^^^^^^^^^^^^^^^^^^^^
  File "/home/airflow/.local/lib/python3.12/site-packages/airflow/models/baseoperator.py", line 401, in wrapper
    return func(self, *args, **kwargs)
           ^^^^^^^^^^^^^^^^^^^^^^^^^^^
  File "/home/airflow/.local/lib/python3.12/site-packages/airflow/operators/bash.py", line 243, in execute
    raise AirflowException(
airflow.exceptions.AirflowException: Bash command failed. The command returned a non-zero exit code 1.

During handling of the above exception, another exception occurred:

Traceback (most recent call last):
  File "/home/airflow/.local/lib/python3.12/site-packages/airflow/models/taskinstance.py", line 1063, in _email_alert
    send_email(task.email, subject, html_content)
  File "/home/airflow/.local/lib/python3.12/site-packages/airflow/utils/email.py", line 80, in send_email
    return backend(
           ^^^^^^^^
  File "/home/airflow/.local/lib/python3.12/site-packages/airflow/utils/email.py", line 154, in send_email_smtp
    send_mime_email(e_from=mail_from, e_to=recipients, mime_msg=msg, conn_id=conn_id, dryrun=dryrun)
  File "/home/airflow/.local/lib/python3.12/site-packages/airflow/utils/email.py", line 273, in send_mime_email
    smtp_conn = _get_smtp_connection(smtp_host, smtp_port, smtp_timeout, smtp_ssl)
                ^^^^^^^^^^^^^^^^^^^^^^^^^^^^^^^^^^^^^^^^^^^^^^^^^^^^^^^^^^^^^^^^^^
  File "/home/airflow/.local/lib/python3.12/site-packages/airflow/utils/email.py", line 317, in _get_smtp_connection
    return smtplib.SMTP(host=host, port=port, timeout=timeout)
           ^^^^^^^^^^^^^^^^^^^^^^^^^^^^^^^^^^^^^^^^^^^^^^^^^^^
  File "/usr/local/lib/python3.12/smtplib.py", line 255, in __init__
    (code, msg) = self.connect(host, port)
                  ^^^^^^^^^^^^^^^^^^^^^^^^
  File "/usr/local/lib/python3.12/smtplib.py", line 341, in connect
    self.sock = self._get_socket(host, port, self.timeout)
                ^^^^^^^^^^^^^^^^^^^^^^^^^^^^^^^^^^^^^^^^^^
  File "/usr/local/lib/python3.12/smtplib.py", line 312, in _get_socket
    return socket.create_connection((host, port), timeout,
           ^^^^^^^^^^^^^^^^^^^^^^^^^^^^^^^^^^^^^^^^^^^^^^^
  File "/usr/local/lib/python3.12/socket.py", line 853, in create_connection
    raise exceptions[0]
  File "/usr/local/lib/python3.12/socket.py", line 838, in create_connection
    sock.connect(sa)
ConnectionRefusedError: [Errno 111] Connection refused

During handling of the above exception, another exception occurred:

Traceback (most recent call last):
  File "/home/airflow/.local/lib/python3.12/site-packages/airflow/models/taskinstance.py", line 877, in _handle_failure
    task_instance.email_alert(error, failure_context["task"])
  File "/home/airflow/.local/lib/python3.12/site-packages/airflow/models/taskinstance.py", line 3163, in email_alert
    _email_alert(task_instance=self, exception=exception, task=task)
  File "/home/airflow/.local/lib/python3.12/site-packages/airflow/models/taskinstance.py", line 1065, in _email_alert
    send_email(task.email, subject, html_content_err)
  File "/home/airflow/.local/lib/python3.12/site-packages/airflow/utils/email.py", line 80, in send_email
    return backend(
           ^^^^^^^^
  File "/home/airflow/.local/lib/python3.12/site-packages/airflow/utils/email.py", line 154, in send_email_smtp
    send_mime_email(e_from=mail_from, e_to=recipients, mime_msg=msg, conn_id=conn_id, dryrun=dryrun)
  File "/home/airflow/.local/lib/python3.12/site-packages/airflow/utils/email.py", line 273, in send_mime_email
    smtp_conn = _get_smtp_connection(smtp_host, smtp_port, smtp_timeout, smtp_ssl)
                ^^^^^^^^^^^^^^^^^^^^^^^^^^^^^^^^^^^^^^^^^^^^^^^^^^^^^^^^^^^^^^^^^^
  File "/home/airflow/.local/lib/python3.12/site-packages/airflow/utils/email.py", line 317, in _get_smtp_connection
    return smtplib.SMTP(host=host, port=port, timeout=timeout)
           ^^^^^^^^^^^^^^^^^^^^^^^^^^^^^^^^^^^^^^^^^^^^^^^^^^^
  File "/usr/local/lib/python3.12/smtplib.py", line 255, in __init__
    (code, msg) = self.connect(host, port)
                  ^^^^^^^^^^^^^^^^^^^^^^^^
  File "/usr/local/lib/python3.12/smtplib.py", line 341, in connect
    self.sock = self._get_socket(host, port, self.timeout)
                ^^^^^^^^^^^^^^^^^^^^^^^^^^^^^^^^^^^^^^^^^^
  File "/usr/local/lib/python3.12/smtplib.py", line 312, in _get_socket
    return socket.create_connection((host, port), timeout,
           ^^^^^^^^^^^^^^^^^^^^^^^^^^^^^^^^^^^^^^^^^^^^^^^
  File "/usr/local/lib/python3.12/socket.py", line 853, in create_connection
    raise exceptions[0]
  File "/usr/local/lib/python3.12/socket.py", line 838, in create_connection
    sock.connect(sa)
ConnectionRefusedError: [Errno 111] Connection refused
[2025-10-10T04:00:30.177+0000] {standard_task_runner.py:110} ERROR - Failed to execute job 314 for task retrain_model (Bash command failed. The command returned a non-zero exit code 1.; 931)
[2025-10-10T04:00:30.230+0000] {local_task_job_runner.py:243} INFO - Task exited with return code 1
[2025-10-10T04:00:30.293+0000] {taskinstance.py:3503} INFO - 0 downstream tasks scheduled from follow-on schedule check
[2025-10-10T04:00:30.298+0000] {local_task_job_runner.py:222} INFO - ::endgroup::
