[2025-10-08T05:28:33.223+0000] {local_task_job_runner.py:120} INFO - ::group::Pre task execution logs
[2025-10-08T05:28:33.347+0000] {taskinstance.py:2076} INFO - Dependencies all met for dep_context=non-requeueable deps ti=<TaskInstance: restaurant_analytics.retrain_model manual__2025-10-08T05:28:21.843987+00:00 [queued]>
[2025-10-08T05:28:33.402+0000] {taskinstance.py:2076} INFO - Dependencies all met for dep_context=requeueable deps ti=<TaskInstance: restaurant_analytics.retrain_model manual__2025-10-08T05:28:21.843987+00:00 [queued]>
[2025-10-08T05:28:33.404+0000] {taskinstance.py:2306} INFO - Starting attempt 1 of 2
[2025-10-08T05:28:33.448+0000] {taskinstance.py:2330} INFO - Executing <Task(BashOperator): retrain_model> on 2025-10-08 05:28:21.843987+00:00
[2025-10-08T05:28:33.512+0000] {warnings.py:112} WARNING - /home/***/.local/lib/python3.12/site-packages/***/task/task_runner/standard_task_runner.py:62: DeprecationWarning: This process (pid=404) is multi-threaded, use of fork() may lead to deadlocks in the child.
  pid = os.fork()

[2025-10-08T05:28:33.516+0000] {standard_task_runner.py:64} INFO - Started process 408 to run task
[2025-10-08T05:28:33.511+0000] {standard_task_runner.py:90} INFO - Running: ['***', 'tasks', 'run', 'restaurant_analytics', 'retrain_model', 'manual__2025-10-08T05:28:21.843987+00:00', '--job-id', '138', '--raw', '--subdir', 'DAGS_FOLDER/restaurant_dag.py', '--cfg-path', '/tmp/tmpy06fb_79']
[2025-10-08T05:28:33.526+0000] {standard_task_runner.py:91} INFO - Job 138: Subtask retrain_model
[2025-10-08T05:28:33.887+0000] {task_command.py:426} INFO - Running <TaskInstance: restaurant_analytics.retrain_model manual__2025-10-08T05:28:21.843987+00:00 [running]> on host c34aac175a74
[2025-10-08T05:28:34.302+0000] {taskinstance.py:2648} INFO - Exporting env vars: AIRFLOW_CTX_DAG_EMAIL='quantruong1918@gmail.com' AIRFLOW_CTX_DAG_OWNER='***' AIRFLOW_CTX_DAG_ID='restaurant_analytics' AIRFLOW_CTX_TASK_ID='retrain_model' AIRFLOW_CTX_EXECUTION_DATE='2025-10-08T05:28:21.843987+00:00' AIRFLOW_CTX_TRY_NUMBER='1' AIRFLOW_CTX_DAG_RUN_ID='manual__2025-10-08T05:28:21.843987+00:00'
[2025-10-08T05:28:34.312+0000] {taskinstance.py:430} INFO - ::endgroup::
[2025-10-08T05:28:34.315+0000] {subprocess.py:63} INFO - Tmp dir root location: /tmp
[2025-10-08T05:28:34.322+0000] {subprocess.py:75} INFO - Running command: ['/usr/bin/bash', '-c', '/opt/spark/bin/spark-submit --master local[*] /opt/***/dags/train_lr.py']
[2025-10-08T05:28:34.376+0000] {subprocess.py:86} INFO - Output:
[2025-10-08T05:28:47.438+0000] {subprocess.py:93} INFO - Traceback (most recent call last):
[2025-10-08T05:28:47.442+0000] {subprocess.py:93} INFO -   File "/opt/***/dags/train_lr.py", line 2, in <module>
[2025-10-08T05:28:47.446+0000] {subprocess.py:93} INFO -     from pyspark.ml.feature import VectorAssembler
[2025-10-08T05:28:47.448+0000] {subprocess.py:93} INFO -   File "/opt/spark/python/lib/pyspark.zip/pyspark/ml/__init__.py", line 22, in <module>
[2025-10-08T05:28:47.450+0000] {subprocess.py:93} INFO -   File "/opt/spark/python/lib/pyspark.zip/pyspark/ml/base.py", line 40, in <module>
[2025-10-08T05:28:47.451+0000] {subprocess.py:93} INFO -   File "/opt/spark/python/lib/pyspark.zip/pyspark/ml/param/__init__.py", line 32, in <module>
[2025-10-08T05:28:47.452+0000] {subprocess.py:93} INFO - ModuleNotFoundError: No module named 'numpy'
[2025-10-08T05:28:47.569+0000] {subprocess.py:93} INFO - 25/10/08 05:28:47 INFO ShutdownHookManager: Shutdown hook called
[2025-10-08T05:28:47.578+0000] {subprocess.py:93} INFO - 25/10/08 05:28:47 INFO ShutdownHookManager: Deleting directory /tmp/spark-6e665403-939e-4b64-9d71-b3d57f7bfc5d
[2025-10-08T05:28:47.714+0000] {subprocess.py:97} INFO - Command exited with return code 1
[2025-10-08T05:28:47.718+0000] {taskinstance.py:441} INFO - ::group::Post task execution logs
[2025-10-08T05:28:47.747+0000] {taskinstance.py:2905} ERROR - Task failed with exception
Traceback (most recent call last):
  File "/home/airflow/.local/lib/python3.12/site-packages/airflow/models/taskinstance.py", line 465, in _execute_task
    result = _execute_callable(context=context, **execute_callable_kwargs)
             ^^^^^^^^^^^^^^^^^^^^^^^^^^^^^^^^^^^^^^^^^^^^^^^^^^^^^^^^^^^^^
  File "/home/airflow/.local/lib/python3.12/site-packages/airflow/models/taskinstance.py", line 432, in _execute_callable
    return execute_callable(context=context, **execute_callable_kwargs)
           ^^^^^^^^^^^^^^^^^^^^^^^^^^^^^^^^^^^^^^^^^^^^^^^^^^^^^^^^^^^^
  File "/home/airflow/.local/lib/python3.12/site-packages/airflow/models/baseoperator.py", line 401, in wrapper
    return func(self, *args, **kwargs)
           ^^^^^^^^^^^^^^^^^^^^^^^^^^^
  File "/home/airflow/.local/lib/python3.12/site-packages/airflow/operators/bash.py", line 243, in execute
    raise AirflowException(
airflow.exceptions.AirflowException: Bash command failed. The command returned a non-zero exit code 1.
[2025-10-08T05:28:47.765+0000] {taskinstance.py:1206} INFO - Marking task as UP_FOR_RETRY. dag_id=restaurant_analytics, task_id=retrain_model, run_id=manual__2025-10-08T05:28:21.843987+00:00, execution_date=20251008T052821, start_date=20251008T052833, end_date=20251008T052847
[2025-10-08T05:28:47.829+0000] {warnings.py:112} WARNING - /home/***/.local/lib/python3.12/site-packages/***/utils/email.py:154: RemovedInAirflow3Warning: Fetching SMTP credentials from configuration variables will be deprecated in a future release. Please set credentials using a connection instead.
  send_mime_email(e_from=mail_from, e_to=recipients, mime_msg=msg, conn_id=conn_id, dryrun=dryrun)

[2025-10-08T05:28:47.830+0000] {configuration.py:1053} WARNING - section/key [smtp/smtp_user] not found in config
[2025-10-08T05:28:47.831+0000] {email.py:271} INFO - Email alerting: attempt 1
[2025-10-08T05:28:47.855+0000] {configuration.py:1053} WARNING - section/key [smtp/smtp_user] not found in config
[2025-10-08T05:28:47.859+0000] {email.py:271} INFO - Email alerting: attempt 1
[2025-10-08T05:28:47.861+0000] {taskinstance.py:879} ERROR - Failed to send email to: ['quantruong1918@gmail.com']
Traceback (most recent call last):
  File "/home/airflow/.local/lib/python3.12/site-packages/airflow/models/taskinstance.py", line 2479, in _run_raw_task
    self._execute_task_with_callbacks(context, test_mode, session=session)
  File "/home/airflow/.local/lib/python3.12/site-packages/airflow/models/taskinstance.py", line 2676, in _execute_task_with_callbacks
    result = self._execute_task(context, task_orig)
             ^^^^^^^^^^^^^^^^^^^^^^^^^^^^^^^^^^^^^^
  File "/home/airflow/.local/lib/python3.12/site-packages/airflow/models/taskinstance.py", line 2701, in _execute_task
    return _execute_task(self, context, task_orig)
           ^^^^^^^^^^^^^^^^^^^^^^^^^^^^^^^^^^^^^^^
  File "/home/airflow/.local/lib/python3.12/site-packages/airflow/models/taskinstance.py", line 465, in _execute_task
    result = _execute_callable(context=context, **execute_callable_kwargs)
             ^^^^^^^^^^^^^^^^^^^^^^^^^^^^^^^^^^^^^^^^^^^^^^^^^^^^^^^^^^^^^
  File "/home/airflow/.local/lib/python3.12/site-packages/airflow/models/taskinstance.py", line 432, in _execute_callable
    return execute_callable(context=context, **execute_callable_kwargs)
           ^^^^^^^^^^^^^^^^^^^^^^^^^^^^^^^^^^^^^^^^^^^^^^^^^^^^^^^^^^^^
  File "/home/airflow/.local/lib/python3.12/site-packages/airflow/models/baseoperator.py", line 401, in wrapper
    return func(self, *args, **kwargs)
           ^^^^^^^^^^^^^^^^^^^^^^^^^^^
  File "/home/airflow/.local/lib/python3.12/site-packages/airflow/operators/bash.py", line 243, in execute
    raise AirflowException(
airflow.exceptions.AirflowException: Bash command failed. The command returned a non-zero exit code 1.

During handling of the above exception, another exception occurred:

Traceback (most recent call last):
  File "/home/airflow/.local/lib/python3.12/site-packages/airflow/models/taskinstance.py", line 1063, in _email_alert
    send_email(task.email, subject, html_content)
  File "/home/airflow/.local/lib/python3.12/site-packages/airflow/utils/email.py", line 80, in send_email
    return backend(
           ^^^^^^^^
  File "/home/airflow/.local/lib/python3.12/site-packages/airflow/utils/email.py", line 154, in send_email_smtp
    send_mime_email(e_from=mail_from, e_to=recipients, mime_msg=msg, conn_id=conn_id, dryrun=dryrun)
  File "/home/airflow/.local/lib/python3.12/site-packages/airflow/utils/email.py", line 273, in send_mime_email
    smtp_conn = _get_smtp_connection(smtp_host, smtp_port, smtp_timeout, smtp_ssl)
                ^^^^^^^^^^^^^^^^^^^^^^^^^^^^^^^^^^^^^^^^^^^^^^^^^^^^^^^^^^^^^^^^^^
  File "/home/airflow/.local/lib/python3.12/site-packages/airflow/utils/email.py", line 317, in _get_smtp_connection
    return smtplib.SMTP(host=host, port=port, timeout=timeout)
           ^^^^^^^^^^^^^^^^^^^^^^^^^^^^^^^^^^^^^^^^^^^^^^^^^^^
  File "/usr/local/lib/python3.12/smtplib.py", line 255, in __init__
    (code, msg) = self.connect(host, port)
                  ^^^^^^^^^^^^^^^^^^^^^^^^
  File "/usr/local/lib/python3.12/smtplib.py", line 341, in connect
    self.sock = self._get_socket(host, port, self.timeout)
                ^^^^^^^^^^^^^^^^^^^^^^^^^^^^^^^^^^^^^^^^^^
  File "/usr/local/lib/python3.12/smtplib.py", line 312, in _get_socket
    return socket.create_connection((host, port), timeout,
           ^^^^^^^^^^^^^^^^^^^^^^^^^^^^^^^^^^^^^^^^^^^^^^^
  File "/usr/local/lib/python3.12/socket.py", line 853, in create_connection
    raise exceptions[0]
  File "/usr/local/lib/python3.12/socket.py", line 838, in create_connection
    sock.connect(sa)
ConnectionRefusedError: [Errno 111] Connection refused

During handling of the above exception, another exception occurred:

Traceback (most recent call last):
  File "/home/airflow/.local/lib/python3.12/site-packages/airflow/models/taskinstance.py", line 877, in _handle_failure
    task_instance.email_alert(error, failure_context["task"])
  File "/home/airflow/.local/lib/python3.12/site-packages/airflow/models/taskinstance.py", line 3163, in email_alert
    _email_alert(task_instance=self, exception=exception, task=task)
  File "/home/airflow/.local/lib/python3.12/site-packages/airflow/models/taskinstance.py", line 1065, in _email_alert
    send_email(task.email, subject, html_content_err)
  File "/home/airflow/.local/lib/python3.12/site-packages/airflow/utils/email.py", line 80, in send_email
    return backend(
           ^^^^^^^^
  File "/home/airflow/.local/lib/python3.12/site-packages/airflow/utils/email.py", line 154, in send_email_smtp
    send_mime_email(e_from=mail_from, e_to=recipients, mime_msg=msg, conn_id=conn_id, dryrun=dryrun)
  File "/home/airflow/.local/lib/python3.12/site-packages/airflow/utils/email.py", line 273, in send_mime_email
    smtp_conn = _get_smtp_connection(smtp_host, smtp_port, smtp_timeout, smtp_ssl)
                ^^^^^^^^^^^^^^^^^^^^^^^^^^^^^^^^^^^^^^^^^^^^^^^^^^^^^^^^^^^^^^^^^^
  File "/home/airflow/.local/lib/python3.12/site-packages/airflow/utils/email.py", line 317, in _get_smtp_connection
    return smtplib.SMTP(host=host, port=port, timeout=timeout)
           ^^^^^^^^^^^^^^^^^^^^^^^^^^^^^^^^^^^^^^^^^^^^^^^^^^^
  File "/usr/local/lib/python3.12/smtplib.py", line 255, in __init__
    (code, msg) = self.connect(host, port)
                  ^^^^^^^^^^^^^^^^^^^^^^^^
  File "/usr/local/lib/python3.12/smtplib.py", line 341, in connect
    self.sock = self._get_socket(host, port, self.timeout)
                ^^^^^^^^^^^^^^^^^^^^^^^^^^^^^^^^^^^^^^^^^^
  File "/usr/local/lib/python3.12/smtplib.py", line 312, in _get_socket
    return socket.create_connection((host, port), timeout,
           ^^^^^^^^^^^^^^^^^^^^^^^^^^^^^^^^^^^^^^^^^^^^^^^
  File "/usr/local/lib/python3.12/socket.py", line 853, in create_connection
    raise exceptions[0]
  File "/usr/local/lib/python3.12/socket.py", line 838, in create_connection
    sock.connect(sa)
ConnectionRefusedError: [Errno 111] Connection refused
[2025-10-08T05:28:47.921+0000] {standard_task_runner.py:110} ERROR - Failed to execute job 138 for task retrain_model (Bash command failed. The command returned a non-zero exit code 1.; 408)
[2025-10-08T05:28:47.973+0000] {local_task_job_runner.py:243} INFO - Task exited with return code 1
[2025-10-08T05:28:48.022+0000] {taskinstance.py:3503} INFO - 0 downstream tasks scheduled from follow-on schedule check
[2025-10-08T05:28:48.034+0000] {local_task_job_runner.py:222} INFO - ::endgroup::
