[2025-10-08T02:30:51.940+0000] {local_task_job_runner.py:120} INFO - ::group::Pre task execution logs
[2025-10-08T02:30:52.366+0000] {taskinstance.py:2076} INFO - Dependencies all met for dep_context=non-requeueable deps ti=<TaskInstance: restaurant_analytics.retrain_model scheduled__2025-10-07T15:00:00+00:00 [queued]>
[2025-10-08T02:30:52.447+0000] {taskinstance.py:2076} INFO - Dependencies all met for dep_context=requeueable deps ti=<TaskInstance: restaurant_analytics.retrain_model scheduled__2025-10-07T15:00:00+00:00 [queued]>
[2025-10-08T02:30:52.449+0000] {taskinstance.py:2306} INFO - Starting attempt 2 of 2
[2025-10-08T02:30:52.726+0000] {taskinstance.py:2330} INFO - Executing <Task(BashOperator): retrain_model> on 2025-10-07 15:00:00+00:00
[2025-10-08T02:30:52.811+0000] {warnings.py:112} WARNING - /home/***/.local/lib/python3.12/site-packages/***/task/task_runner/standard_task_runner.py:62: DeprecationWarning: This process (pid=82) is multi-threaded, use of fork() may lead to deadlocks in the child.
  pid = os.fork()

[2025-10-08T02:30:52.835+0000] {standard_task_runner.py:64} INFO - Started process 91 to run task
[2025-10-08T02:30:52.814+0000] {standard_task_runner.py:90} INFO - Running: ['***', 'tasks', 'run', 'restaurant_analytics', 'retrain_model', 'scheduled__2025-10-07T15:00:00+00:00', '--job-id', '96', '--raw', '--subdir', 'DAGS_FOLDER/restaurant_dag.py', '--cfg-path', '/tmp/tmpqxat415u']
[2025-10-08T02:30:52.870+0000] {standard_task_runner.py:91} INFO - Job 96: Subtask retrain_model
[2025-10-08T02:30:53.793+0000] {task_command.py:426} INFO - Running <TaskInstance: restaurant_analytics.retrain_model scheduled__2025-10-07T15:00:00+00:00 [running]> on host c34aac175a74
[2025-10-08T02:30:54.921+0000] {taskinstance.py:2648} INFO - Exporting env vars: AIRFLOW_CTX_DAG_EMAIL='quantruong1918@gmail.com' AIRFLOW_CTX_DAG_OWNER='***' AIRFLOW_CTX_DAG_ID='restaurant_analytics' AIRFLOW_CTX_TASK_ID='retrain_model' AIRFLOW_CTX_EXECUTION_DATE='2025-10-07T15:00:00+00:00' AIRFLOW_CTX_TRY_NUMBER='2' AIRFLOW_CTX_DAG_RUN_ID='scheduled__2025-10-07T15:00:00+00:00'
[2025-10-08T02:30:54.944+0000] {taskinstance.py:430} INFO - ::endgroup::
[2025-10-08T02:30:54.948+0000] {subprocess.py:63} INFO - Tmp dir root location: /tmp
[2025-10-08T02:30:54.957+0000] {subprocess.py:75} INFO - Running command: ['/usr/bin/bash', '-c', 'spark-submit --master local[*] /opt/***/dags/train_lr.py']
[2025-10-08T02:30:55.306+0000] {subprocess.py:86} INFO - Output:
[2025-10-08T02:30:55.350+0000] {subprocess.py:93} INFO - /usr/bin/bash: line 1: spark-submit: command not found
[2025-10-08T02:30:55.352+0000] {subprocess.py:97} INFO - Command exited with return code 127
[2025-10-08T02:30:55.360+0000] {taskinstance.py:441} INFO - ::group::Post task execution logs
[2025-10-08T02:30:55.458+0000] {taskinstance.py:2905} ERROR - Task failed with exception
Traceback (most recent call last):
  File "/home/airflow/.local/lib/python3.12/site-packages/airflow/models/taskinstance.py", line 465, in _execute_task
    result = _execute_callable(context=context, **execute_callable_kwargs)
             ^^^^^^^^^^^^^^^^^^^^^^^^^^^^^^^^^^^^^^^^^^^^^^^^^^^^^^^^^^^^^
  File "/home/airflow/.local/lib/python3.12/site-packages/airflow/models/taskinstance.py", line 432, in _execute_callable
    return execute_callable(context=context, **execute_callable_kwargs)
           ^^^^^^^^^^^^^^^^^^^^^^^^^^^^^^^^^^^^^^^^^^^^^^^^^^^^^^^^^^^^
  File "/home/airflow/.local/lib/python3.12/site-packages/airflow/models/baseoperator.py", line 401, in wrapper
    return func(self, *args, **kwargs)
           ^^^^^^^^^^^^^^^^^^^^^^^^^^^
  File "/home/airflow/.local/lib/python3.12/site-packages/airflow/operators/bash.py", line 243, in execute
    raise AirflowException(
airflow.exceptions.AirflowException: Bash command failed. The command returned a non-zero exit code 127.
[2025-10-08T02:30:55.648+0000] {taskinstance.py:1206} INFO - Marking task as FAILED. dag_id=restaurant_analytics, task_id=retrain_model, run_id=scheduled__2025-10-07T15:00:00+00:00, execution_date=20251007T150000, start_date=20251008T023052, end_date=20251008T023055
[2025-10-08T02:30:56.196+0000] {standard_task_runner.py:110} ERROR - Failed to execute job 96 for task retrain_model (Bash command failed. The command returned a non-zero exit code 127.; 91)
[2025-10-08T02:30:56.321+0000] {local_task_job_runner.py:243} INFO - Task exited with return code 1
[2025-10-08T02:30:56.635+0000] {local_task_job_runner.py:222} INFO - ::endgroup::
