[2025-10-09T06:10:19.053+0000] {local_task_job_runner.py:120} INFO - ::group::Pre task execution logs
[2025-10-09T06:10:19.123+0000] {taskinstance.py:2076} INFO - Dependencies all met for dep_context=non-requeueable deps ti=<TaskInstance: restaurant_analytics.run_spark_stream scheduled__2025-10-09T03:00:00+00:00 [queued]>
[2025-10-09T06:10:19.150+0000] {taskinstance.py:2076} INFO - Dependencies all met for dep_context=requeueable deps ti=<TaskInstance: restaurant_analytics.run_spark_stream scheduled__2025-10-09T03:00:00+00:00 [queued]>
[2025-10-09T06:10:19.153+0000] {taskinstance.py:2306} INFO - Starting attempt 2 of 3
[2025-10-09T06:10:19.198+0000] {taskinstance.py:2330} INFO - Executing <Task(BashOperator): run_spark_stream> on 2025-10-09 03:00:00+00:00
[2025-10-09T06:10:19.218+0000] {warnings.py:112} WARNING - /home/***/.local/lib/python3.12/site-packages/***/task/task_runner/standard_task_runner.py:62: DeprecationWarning: This process (pid=337) is multi-threaded, use of fork() may lead to deadlocks in the child.
  pid = os.fork()

[2025-10-09T06:10:19.223+0000] {standard_task_runner.py:64} INFO - Started process 339 to run task
[2025-10-09T06:10:19.223+0000] {standard_task_runner.py:90} INFO - Running: ['***', 'tasks', 'run', 'restaurant_analytics', 'run_spark_stream', 'scheduled__2025-10-09T03:00:00+00:00', '--job-id', '245', '--raw', '--subdir', 'DAGS_FOLDER/restaurant_dag.py', '--cfg-path', '/tmp/tmpt09qm69n']
[2025-10-09T06:10:19.232+0000] {standard_task_runner.py:91} INFO - Job 245: Subtask run_spark_stream
[2025-10-09T06:10:19.429+0000] {task_command.py:426} INFO - Running <TaskInstance: restaurant_analytics.run_spark_stream scheduled__2025-10-09T03:00:00+00:00 [running]> on host 01b28d042a8a
[2025-10-09T06:10:19.710+0000] {taskinstance.py:2648} INFO - Exporting env vars: AIRFLOW_CTX_DAG_EMAIL='quantruong1918@gmail.com' AIRFLOW_CTX_DAG_OWNER='***' AIRFLOW_CTX_DAG_ID='restaurant_analytics' AIRFLOW_CTX_TASK_ID='run_spark_stream' AIRFLOW_CTX_EXECUTION_DATE='2025-10-09T03:00:00+00:00' AIRFLOW_CTX_TRY_NUMBER='2' AIRFLOW_CTX_DAG_RUN_ID='scheduled__2025-10-09T03:00:00+00:00'
[2025-10-09T06:10:19.715+0000] {taskinstance.py:430} INFO - ::endgroup::
[2025-10-09T06:10:19.718+0000] {subprocess.py:63} INFO - Tmp dir root location: /tmp
[2025-10-09T06:10:19.721+0000] {subprocess.py:75} INFO - Running command: ['/usr/bin/bash', '-c', 'export PYSPARK_PYTHON=/usr/local/bin/python && export PYSPARK_DRIVER_PYTHON=/usr/local/bin/python && /opt/spark/bin/spark-submit --master local[*] --packages org.apache.spark:spark-sql-kafka-0-10_2.12:3.5.1 /opt/***/dags/spark_streaming.py']
[2025-10-09T06:10:19.760+0000] {subprocess.py:86} INFO - Output:
[2025-10-09T06:10:26.298+0000] {subprocess.py:93} INFO - :: loading settings :: url = jar:file:/opt/spark/jars/ivy-2.5.1.jar!/org/apache/ivy/core/settings/ivysettings.xml
[2025-10-09T06:10:26.654+0000] {subprocess.py:93} INFO - Ivy Default Cache set to: /home/***/.ivy2/cache
[2025-10-09T06:10:26.655+0000] {subprocess.py:93} INFO - The jars for the packages stored in: /home/***/.ivy2/jars
[2025-10-09T06:10:26.687+0000] {subprocess.py:93} INFO - org.apache.spark#spark-sql-kafka-0-10_2.12 added as a dependency
[2025-10-09T06:10:26.694+0000] {subprocess.py:93} INFO - :: resolving dependencies :: org.apache.spark#spark-submit-parent-fb37c946-45bb-4cdb-b741-0a44fa7af7b9;1.0
[2025-10-09T06:10:26.696+0000] {subprocess.py:93} INFO - 	confs: [default]
[2025-10-09T06:10:28.094+0000] {subprocess.py:93} INFO - 	found org.apache.spark#spark-sql-kafka-0-10_2.12;3.5.1 in central
[2025-10-09T06:10:28.474+0000] {subprocess.py:93} INFO - 	found org.apache.spark#spark-token-provider-kafka-0-10_2.12;3.5.1 in central
[2025-10-09T06:10:28.602+0000] {subprocess.py:93} INFO - 	found org.apache.kafka#kafka-clients;3.4.1 in central
[2025-10-09T06:10:28.857+0000] {subprocess.py:93} INFO - 	found org.lz4#lz4-java;1.8.0 in central
[2025-10-09T06:10:29.081+0000] {subprocess.py:93} INFO - 	found org.xerial.snappy#snappy-java;1.1.10.3 in central
[2025-10-09T06:10:29.209+0000] {subprocess.py:93} INFO - 	found org.slf4j#slf4j-api;2.0.7 in central
[2025-10-09T06:10:29.353+0000] {subprocess.py:93} INFO - 	found org.apache.hadoop#hadoop-client-runtime;3.3.4 in central
[2025-10-09T06:10:29.531+0000] {subprocess.py:93} INFO - 	found org.apache.hadoop#hadoop-client-api;3.3.4 in central
[2025-10-09T06:10:29.661+0000] {subprocess.py:93} INFO - 	found commons-logging#commons-logging;1.1.3 in central
[2025-10-09T06:10:29.730+0000] {subprocess.py:93} INFO - 	found com.google.code.findbugs#jsr305;3.0.0 in central
[2025-10-09T06:10:29.797+0000] {subprocess.py:93} INFO - 	found org.apache.commons#commons-pool2;2.11.1 in central
[2025-10-09T06:10:29.906+0000] {subprocess.py:93} INFO - :: resolution report :: resolve 3155ms :: artifacts dl 57ms
[2025-10-09T06:10:29.907+0000] {subprocess.py:93} INFO - 	:: modules in use:
[2025-10-09T06:10:29.908+0000] {subprocess.py:93} INFO - 	com.google.code.findbugs#jsr305;3.0.0 from central in [default]
[2025-10-09T06:10:29.909+0000] {subprocess.py:93} INFO - 	commons-logging#commons-logging;1.1.3 from central in [default]
[2025-10-09T06:10:29.910+0000] {subprocess.py:93} INFO - 	org.apache.commons#commons-pool2;2.11.1 from central in [default]
[2025-10-09T06:10:29.911+0000] {subprocess.py:93} INFO - 	org.apache.hadoop#hadoop-client-api;3.3.4 from central in [default]
[2025-10-09T06:10:29.914+0000] {subprocess.py:93} INFO - 	org.apache.hadoop#hadoop-client-runtime;3.3.4 from central in [default]
[2025-10-09T06:10:29.916+0000] {subprocess.py:93} INFO - 	org.apache.kafka#kafka-clients;3.4.1 from central in [default]
[2025-10-09T06:10:29.917+0000] {subprocess.py:93} INFO - 	org.apache.spark#spark-sql-kafka-0-10_2.12;3.5.1 from central in [default]
[2025-10-09T06:10:29.918+0000] {subprocess.py:93} INFO - 	org.apache.spark#spark-token-provider-kafka-0-10_2.12;3.5.1 from central in [default]
[2025-10-09T06:10:29.919+0000] {subprocess.py:93} INFO - 	org.lz4#lz4-java;1.8.0 from central in [default]
[2025-10-09T06:10:29.920+0000] {subprocess.py:93} INFO - 	org.slf4j#slf4j-api;2.0.7 from central in [default]
[2025-10-09T06:10:29.921+0000] {subprocess.py:93} INFO - 	org.xerial.snappy#snappy-java;1.1.10.3 from central in [default]
[2025-10-09T06:10:29.923+0000] {subprocess.py:93} INFO - 	---------------------------------------------------------------------
[2025-10-09T06:10:29.925+0000] {subprocess.py:93} INFO - 	|                  |            modules            ||   artifacts   |
[2025-10-09T06:10:29.927+0000] {subprocess.py:93} INFO - 	|       conf       | number| search|dwnlded|evicted|| number|dwnlded|
[2025-10-09T06:10:29.928+0000] {subprocess.py:93} INFO - 	---------------------------------------------------------------------
[2025-10-09T06:10:29.929+0000] {subprocess.py:93} INFO - 	|      default     |   11  |   0   |   0   |   0   ||   11  |   0   |
[2025-10-09T06:10:29.930+0000] {subprocess.py:93} INFO - 	---------------------------------------------------------------------
[2025-10-09T06:10:29.931+0000] {subprocess.py:93} INFO - :: retrieving :: org.apache.spark#spark-submit-parent-fb37c946-45bb-4cdb-b741-0a44fa7af7b9
[2025-10-09T06:10:29.933+0000] {subprocess.py:93} INFO - 	confs: [default]
[2025-10-09T06:10:29.949+0000] {subprocess.py:93} INFO - 	0 artifacts copied, 11 already retrieved (0kB/22ms)
[2025-10-09T06:10:31.634+0000] {subprocess.py:93} INFO - 25/10/09 06:10:31 WARN NativeCodeLoader: Unable to load native-hadoop library for your platform... using builtin-java classes where applicable
[2025-10-09T06:10:34.730+0000] {local_task_job_runner.py:313} WARNING - State of this instance has been externally set to restarting. Terminating instance.
[2025-10-09T06:10:34.757+0000] {local_task_job_runner.py:222} INFO - ::endgroup::
[2025-10-09T06:10:34.776+0000] {process_utils.py:132} INFO - Sending 15 to group 339. PIDs of all processes in the group: [340, 451, 339]
[2025-10-09T06:10:34.790+0000] {process_utils.py:87} INFO - Sending the signal 15 to group 339
[2025-10-09T06:10:34.792+0000] {taskinstance.py:2611} ERROR - Received SIGTERM. Terminating subprocesses.
[2025-10-09T06:10:34.798+0000] {subprocess.py:104} INFO - Sending SIGTERM signal to process group
[2025-10-09T06:10:34.800+0000] {taskinstance.py:441} INFO - ::group::Post task execution logs
[2025-10-09T06:10:34.877+0000] {taskinstance.py:2905} ERROR - Task failed with exception
Traceback (most recent call last):
  File "/home/airflow/.local/lib/python3.12/site-packages/airflow/models/taskinstance.py", line 465, in _execute_task
    result = _execute_callable(context=context, **execute_callable_kwargs)
             ^^^^^^^^^^^^^^^^^^^^^^^^^^^^^^^^^^^^^^^^^^^^^^^^^^^^^^^^^^^^^
  File "/home/airflow/.local/lib/python3.12/site-packages/airflow/models/taskinstance.py", line 432, in _execute_callable
    return execute_callable(context=context, **execute_callable_kwargs)
           ^^^^^^^^^^^^^^^^^^^^^^^^^^^^^^^^^^^^^^^^^^^^^^^^^^^^^^^^^^^^
  File "/home/airflow/.local/lib/python3.12/site-packages/airflow/models/baseoperator.py", line 401, in wrapper
    return func(self, *args, **kwargs)
           ^^^^^^^^^^^^^^^^^^^^^^^^^^^
  File "/home/airflow/.local/lib/python3.12/site-packages/airflow/operators/bash.py", line 234, in execute
    result = self.subprocess_hook.run_command(
             ^^^^^^^^^^^^^^^^^^^^^^^^^^^^^^^^^
  File "/home/airflow/.local/lib/python3.12/site-packages/airflow/hooks/subprocess.py", line 91, in run_command
    for raw_line in iter(self.sub_process.stdout.readline, b""):
  File "/home/airflow/.local/lib/python3.12/site-packages/airflow/models/taskinstance.py", line 2613, in signal_handler
    raise AirflowTaskTerminated("Task received SIGTERM signal")
airflow.exceptions.AirflowTaskTerminated: Task received SIGTERM signal
[2025-10-09T06:10:34.938+0000] {taskinstance.py:1206} INFO - Marking task as UP_FOR_RETRY. dag_id=restaurant_analytics, task_id=run_spark_stream, run_id=scheduled__2025-10-09T03:00:00+00:00, execution_date=20251009T030000, start_date=20251009T061019, end_date=20251009T061034
[2025-10-09T06:10:35.136+0000] {warnings.py:112} WARNING - /home/***/.local/lib/python3.12/site-packages/***/utils/email.py:154: RemovedInAirflow3Warning: Fetching SMTP credentials from configuration variables will be deprecated in a future release. Please set credentials using a connection instead.
  send_mime_email(e_from=mail_from, e_to=recipients, mime_msg=msg, conn_id=conn_id, dryrun=dryrun)

[2025-10-09T06:10:35.151+0000] {process_utils.py:80} INFO - Process psutil.Process(pid=451, status='terminated', started='06:10:34') (451) terminated with exit code None
[2025-10-09T06:10:35.153+0000] {configuration.py:1053} WARNING - section/key [smtp/smtp_user] not found in config
[2025-10-09T06:10:35.155+0000] {email.py:271} INFO - Email alerting: attempt 1
[2025-10-09T06:10:35.213+0000] {configuration.py:1053} WARNING - section/key [smtp/smtp_user] not found in config
[2025-10-09T06:10:35.231+0000] {email.py:271} INFO - Email alerting: attempt 1
[2025-10-09T06:10:35.234+0000] {taskinstance.py:879} ERROR - Failed to send email to: ['quantruong1918@gmail.com']
Traceback (most recent call last):
  File "/home/airflow/.local/lib/python3.12/site-packages/airflow/models/taskinstance.py", line 2479, in _run_raw_task
    self._execute_task_with_callbacks(context, test_mode, session=session)
  File "/home/airflow/.local/lib/python3.12/site-packages/airflow/models/taskinstance.py", line 2676, in _execute_task_with_callbacks
    result = self._execute_task(context, task_orig)
             ^^^^^^^^^^^^^^^^^^^^^^^^^^^^^^^^^^^^^^
  File "/home/airflow/.local/lib/python3.12/site-packages/airflow/models/taskinstance.py", line 2701, in _execute_task
    return _execute_task(self, context, task_orig)
           ^^^^^^^^^^^^^^^^^^^^^^^^^^^^^^^^^^^^^^^
  File "/home/airflow/.local/lib/python3.12/site-packages/airflow/models/taskinstance.py", line 465, in _execute_task
    result = _execute_callable(context=context, **execute_callable_kwargs)
             ^^^^^^^^^^^^^^^^^^^^^^^^^^^^^^^^^^^^^^^^^^^^^^^^^^^^^^^^^^^^^
  File "/home/airflow/.local/lib/python3.12/site-packages/airflow/models/taskinstance.py", line 432, in _execute_callable
    return execute_callable(context=context, **execute_callable_kwargs)
           ^^^^^^^^^^^^^^^^^^^^^^^^^^^^^^^^^^^^^^^^^^^^^^^^^^^^^^^^^^^^
  File "/home/airflow/.local/lib/python3.12/site-packages/airflow/models/baseoperator.py", line 401, in wrapper
    return func(self, *args, **kwargs)
           ^^^^^^^^^^^^^^^^^^^^^^^^^^^
  File "/home/airflow/.local/lib/python3.12/site-packages/airflow/operators/bash.py", line 234, in execute
    result = self.subprocess_hook.run_command(
             ^^^^^^^^^^^^^^^^^^^^^^^^^^^^^^^^^
  File "/home/airflow/.local/lib/python3.12/site-packages/airflow/hooks/subprocess.py", line 91, in run_command
    for raw_line in iter(self.sub_process.stdout.readline, b""):
  File "/home/airflow/.local/lib/python3.12/site-packages/airflow/models/taskinstance.py", line 2613, in signal_handler
    raise AirflowTaskTerminated("Task received SIGTERM signal")
airflow.exceptions.AirflowTaskTerminated: Task received SIGTERM signal

During handling of the above exception, another exception occurred:

Traceback (most recent call last):
  File "/home/airflow/.local/lib/python3.12/site-packages/airflow/models/taskinstance.py", line 1063, in _email_alert
    send_email(task.email, subject, html_content)
  File "/home/airflow/.local/lib/python3.12/site-packages/airflow/utils/email.py", line 80, in send_email
    return backend(
           ^^^^^^^^
  File "/home/airflow/.local/lib/python3.12/site-packages/airflow/utils/email.py", line 154, in send_email_smtp
    send_mime_email(e_from=mail_from, e_to=recipients, mime_msg=msg, conn_id=conn_id, dryrun=dryrun)
  File "/home/airflow/.local/lib/python3.12/site-packages/airflow/utils/email.py", line 273, in send_mime_email
    smtp_conn = _get_smtp_connection(smtp_host, smtp_port, smtp_timeout, smtp_ssl)
                ^^^^^^^^^^^^^^^^^^^^^^^^^^^^^^^^^^^^^^^^^^^^^^^^^^^^^^^^^^^^^^^^^^
  File "/home/airflow/.local/lib/python3.12/site-packages/airflow/utils/email.py", line 317, in _get_smtp_connection
    return smtplib.SMTP(host=host, port=port, timeout=timeout)
           ^^^^^^^^^^^^^^^^^^^^^^^^^^^^^^^^^^^^^^^^^^^^^^^^^^^
  File "/usr/local/lib/python3.12/smtplib.py", line 255, in __init__
    (code, msg) = self.connect(host, port)
                  ^^^^^^^^^^^^^^^^^^^^^^^^
  File "/usr/local/lib/python3.12/smtplib.py", line 341, in connect
    self.sock = self._get_socket(host, port, self.timeout)
                ^^^^^^^^^^^^^^^^^^^^^^^^^^^^^^^^^^^^^^^^^^
  File "/usr/local/lib/python3.12/smtplib.py", line 312, in _get_socket
    return socket.create_connection((host, port), timeout,
           ^^^^^^^^^^^^^^^^^^^^^^^^^^^^^^^^^^^^^^^^^^^^^^^
  File "/usr/local/lib/python3.12/socket.py", line 853, in create_connection
    raise exceptions[0]
  File "/usr/local/lib/python3.12/socket.py", line 838, in create_connection
    sock.connect(sa)
ConnectionRefusedError: [Errno 111] Connection refused

During handling of the above exception, another exception occurred:

Traceback (most recent call last):
  File "/home/airflow/.local/lib/python3.12/site-packages/airflow/models/taskinstance.py", line 877, in _handle_failure
    task_instance.email_alert(error, failure_context["task"])
  File "/home/airflow/.local/lib/python3.12/site-packages/airflow/models/taskinstance.py", line 3163, in email_alert
    _email_alert(task_instance=self, exception=exception, task=task)
  File "/home/airflow/.local/lib/python3.12/site-packages/airflow/models/taskinstance.py", line 1065, in _email_alert
    send_email(task.email, subject, html_content_err)
  File "/home/airflow/.local/lib/python3.12/site-packages/airflow/utils/email.py", line 80, in send_email
    return backend(
           ^^^^^^^^
  File "/home/airflow/.local/lib/python3.12/site-packages/airflow/utils/email.py", line 154, in send_email_smtp
    send_mime_email(e_from=mail_from, e_to=recipients, mime_msg=msg, conn_id=conn_id, dryrun=dryrun)
  File "/home/airflow/.local/lib/python3.12/site-packages/airflow/utils/email.py", line 273, in send_mime_email
    smtp_conn = _get_smtp_connection(smtp_host, smtp_port, smtp_timeout, smtp_ssl)
                ^^^^^^^^^^^^^^^^^^^^^^^^^^^^^^^^^^^^^^^^^^^^^^^^^^^^^^^^^^^^^^^^^^
  File "/home/airflow/.local/lib/python3.12/site-packages/airflow/utils/email.py", line 317, in _get_smtp_connection
    return smtplib.SMTP(host=host, port=port, timeout=timeout)
           ^^^^^^^^^^^^^^^^^^^^^^^^^^^^^^^^^^^^^^^^^^^^^^^^^^^
  File "/usr/local/lib/python3.12/smtplib.py", line 255, in __init__
    (code, msg) = self.connect(host, port)
                  ^^^^^^^^^^^^^^^^^^^^^^^^
  File "/usr/local/lib/python3.12/smtplib.py", line 341, in connect
    self.sock = self._get_socket(host, port, self.timeout)
                ^^^^^^^^^^^^^^^^^^^^^^^^^^^^^^^^^^^^^^^^^^
  File "/usr/local/lib/python3.12/smtplib.py", line 312, in _get_socket
    return socket.create_connection((host, port), timeout,
           ^^^^^^^^^^^^^^^^^^^^^^^^^^^^^^^^^^^^^^^^^^^^^^^
  File "/usr/local/lib/python3.12/socket.py", line 853, in create_connection
    raise exceptions[0]
  File "/usr/local/lib/python3.12/socket.py", line 838, in create_connection
    sock.connect(sa)
ConnectionRefusedError: [Errno 111] Connection refused
[2025-10-09T06:10:35.461+0000] {process_utils.py:80} INFO - Process psutil.Process(pid=340, status='terminated', started='06:10:19') (340) terminated with exit code None
[2025-10-09T06:10:35.466+0000] {process_utils.py:80} INFO - Process psutil.Process(pid=339, status='terminated', exitcode=2, started='06:10:18') (339) terminated with exit code 2
